Workbook

Sheet راهنما
A1: قالب ساده جمع‌آوری اطلاعات مدرسه
A2: این فایل فقط برای کلاس‌بندی، ثبت دانش‌آموزان و چهار شاخص اصلی ارزیابی استفاده می‌شود.
A4: ۱ | B4: کلاس‌بندی | C4: کد مدرسه، سال تحصیلی، کد و نام کلاس، پایه و ظرفیت را وارد کنید.
A5: ۲ | B5: دانش‌آموزان | C5: کد محلی، کد ملی، شماره دانش‌آموزی، نام، نام خانوادگی، جنسیت، تاریخ تولد و کد کلاس را وارد کنید.
A6: ۳ | B6: ثبت اطلاعات | C6: برای هر دانش‌آموز و ماه، چهار امتیاز نمرات درسی، انجام تکالیف، مشارکت در کلاس و حضور و غیاب را وارد کنید.
A7: ۴ | B7: مقیاس امتیاز | C7: تمام امتیازها باید عدد صحیح بین ۰ تا ۵ باشند؛ ۰ ضعیف‌ترین و ۵ بهترین وضعیت است.
A8: ۵ | B8: تاریخ تولد | C8: تاریخ تولد را میلادی و با قالب YYYY-MM-DD وارد کنید؛ نمونه: 2012-09-05
A9: ۶ | B9: سلول‌های زرد | C9: فقط سلول‌های زرد برای ورود اطلاعات هستند؛ سلول‌های آبی به‌صورت خودکار محاسبه می‌شوند.
A10: ۷ | B10: اطلاعات ناقص | C10: اگر هر چهار شاخص تکمیل نشده باشد، نتیجه «موقت - اطلاعات ناقص» نمایش داده می‌شود.
A11: ۸ | B11: عدم تغییر ساختار | C11: نام شیت‌ها، عنوان ستون‌ها، ترتیب ستون‌ها و فرمول‌ها را تغییر ندهید.

Sheet کلاس‌بندی
A1: کلاس‌بندی مدرسه
A2: هر کلاس را فقط یک‌بار وارد کنید. ظرفیت ثبت‌شده و تعداد دانش‌آموزان تخصیص‌یافته به‌صورت خودکار مقایسه می‌شوند.
A4: ردیف | B4: کد مدرسه | C4: سال تحصیلی | D4: کد کلاس | E4: نام کلاس | F4: پایه تحصیلی | G4: ظرفیت | H4: تعداد ثبت‌شده | I4: وضعیت
A5: 1 | H5: =IF(D5="","",COUNTIF('دانش‌آموزان'!$I$5:$I$104,D5)) | I5: =IF(D5="","",IF(COUNTIF($D$5:$D$34,D5)>1,"کد تکراری",IF(H5>G5,"بیش از ظرفیت","معتبر")))
A6: 2 | H6: =IF(D6="","",COUNTIF('دانش‌آموزان'!$I$5:$I$104,D6)) | I6: =IF(D6="","",IF(COUNTIF($D$5:$D$34,D6)>1,"کد تکراری",IF(H6>G6,"بیش از ظرفیت","معتبر")))
A7: 3 | H7: =IF(D7="","",COUNTIF('دانش‌آموزان'!$I$5:$I$104,D7)) | I7: =IF(D7="","",IF(COUNTIF($D$5:$D$34,D7)>1,"کد تکراری",IF(H7>G7,"بیش از ظرفیت","معتبر")))
A8: 4 | H8: =IF(D8="","",COUNTIF('دانش‌آموزان'!$I$5:$I$104,D8)) | I8: =IF(D8="","",IF(COUNTIF($D$5:$D$34,D8)>1,"کد تکراری",IF(H8>G8,"بیش از ظرفیت","معتبر")))
A9: 5 | H9: =IF(D9="","",COUNTIF('دانش‌آموزان'!$I$5:$I$104,D9)) | I9: =IF(D9="","",IF(COUNTIF($D$5:$D$34,D9)>1,"کد تکراری",IF(H9>G9,"بیش از ظرفیت","معتبر")))
A10: 6 | H10: =IF(D10="","",COUNTIF('دانش‌آموزان'!$I$5:$I$104,D10)) | I10: =IF(D10="","",IF(COUNTIF($D$5:$D$34,D10)>1,"کد تکراری",IF(H10>G10,"بیش از ظرفیت","معتبر")))
A11: 7 | H11: =IF(D11="","",COUNTIF('دانش‌آموزان'!$I$5:$I$104,D11)) | I11: =IF(D11="","",IF(COUNTIF($D$5:$D$34,D11)>1,"کد تکراری",IF(H11>G11,"بیش از ظرفیت","معتبر")))
A12: 8 | H12: =IF(D12="","",COUNTIF('دانش‌آموزان'!$I$5:$I$104,D12)) | I12: =IF(D12="","",IF(COUNTIF($D$5:$D$34,D12)>1,"کد تکراری",IF(H12>G12,"بیش از ظرفیت","معتبر")))
A13: 9 | H13: =IF(D13="","",COUNTIF('دانش‌آموزان'!$I$5:$I$104,D13)) | I13: =IF(D13="","",IF(COUNTIF($D$5:$D$34,D13)>1,"کد تکراری",IF(H13>G13,"بیش از ظرفیت","معتبر")))
A14: 10 | H14: =IF(D14="","",COUNTIF('دانش‌آموزان'!$I$5:$I$104,D14)) | I14: =IF(D14="","",IF(COUNTIF($D$5:$D$34,D14)>1,"کد تکراری",IF(H14>G14,"بیش از ظرفیت","معتبر")))
A15: 11 | H15: =IF(D15="","",COUNTIF('دانش‌آموزان'!$I$5:$I$104,D15)) | I15: =IF(D15="","",IF(COUNTIF($D$5:$D$34,D15)>1,"کد تکراری",IF(H15>G15,"بیش از ظرفیت","معتبر")))
A16: 12 | H16: =IF(D16="","",COUNTIF('دانش‌آموزان'!$I$5:$I$104,D16)) | I16: =IF(D16="","",IF(COUNTIF($D$5:$D$34,D16)>1,"کد تکراری",IF(H16>G16,"بیش از ظرفیت","معتبر")))
... A34: 30 | H34: =IF(D34="","",COUNTIF('دانش‌آموزان'!$I$5:$I$104,D34)) | I34: =IF(D34="","",IF(COUNTIF($D$5:$D$34,D34)>1,"کد تکراری",IF(H34>G34,"بیش از ظرفیت","معتبر")))

Sheet دانش‌آموزان
A1: فهرست دانش‌آموزان
A2: برای هر دانش‌آموز یک ردیف تکمیل کنید. کد محلی ۱ تا ۱۰۰ از قبل ساخته شده و مبنای گزارش‌های همین فایل است.
A4: ردیف | B4: کد محلی | C4: کد ملی | D4: شماره دانش‌آموزی | E4: نام | F4: نام خانوادگی | G4: جنسیت | H4: تاریخ تولد | I4: کد کلاس | J4: نام کلاس | K4: پایه | L4: وضعیت اطلاعات
A5: 1 | B5: 1 | J5: =IF(I5="","",IFERROR(INDEX('کلاس‌بندی'!$E$5:$E$34,MATCH(I5,'کلاس‌بندی'!$D$5:$D$34,0)),"کد کلاس نامعتبر")) | K5: =IF(I5="","",IFERROR(INDEX('کلاس‌بندی'!$F$5:$F$34,MATCH(I5,'کلاس‌بندی'!$D$5:$D$34,0)),"")) | L5: =IF(COUNTA(C5:I5)=0,"",IF(AND(LEN(C5)=10,D5<>"",E5<>"",F5<>"",G5<>"",H5<>"",I5<>""),"کامل","ناقص"))
A6: 2 | B6: 2 | J6: =IF(I6="","",IFERROR(INDEX('کلاس‌بندی'!$E$5:$E$34,MATCH(I6,'کلاس‌بندی'!$D$5:$D$34,0)),"کد کلاس نامعتبر")) | K6: =IF(I6="","",IFERROR(INDEX('کلاس‌بندی'!$F$5:$F$34,MATCH(I6,'کلاس‌بندی'!$D$5:$D$34,0)),"")) | L6: =IF(COUNTA(C6:I6)=0,"",IF(AND(LEN(C6)=10,D6<>"",E6<>"",F6<>"",G6<>"",H6<>"",I6<>""),"کامل","ناقص"))
A7: 3 | B7: 3 | J7: =IF(I7="","",IFERROR(INDEX('کلاس‌بندی'!$E$5:$E$34,MATCH(I7,'کلاس‌بندی'!$D$5:$D$34,0)),"کد کلاس نامعتبر")) | K7: =IF(I7="","",IFERROR(INDEX('کلاس‌بندی'!$F$5:$F$34,MATCH(I7,'کلاس‌بندی'!$D$5:$D$34,0)),"")) | L7: =IF(COUNTA(C7:I7)=0,"",IF(AND(LEN(C7)=10,D7<>"",E7<>"",F7<>"",G7<>"",H7<>"",I7<>""),"کامل","ناقص"))
A8: 4 | B8: 4 | J8: =IF(I8="","",IFERROR(INDEX('کلاس‌بندی'!$E$5:$E$34,MATCH(I8,'کلاس‌بندی'!$D$5:$D$34,0)),"کد کلاس نامعتبر")) | K8: =IF(I8="","",IFERROR(INDEX('کلاس‌بندی'!$F$5:$F$34,MATCH(I8,'کلاس‌بندی'!$D$5:$D$34,0)),"")) | L8: =IF(COUNTA(C8:I8)=0,"",IF(AND(LEN(C8)=10,D8<>"",E8<>"",F8<>"",G8<>"",H8<>"",I8<>""),"کامل","ناقص"))
A9: 5 | B9: 5 | J9: =IF(I9="","",IFERROR(INDEX('کلاس‌بندی'!$E$5:$E$34,MATCH(I9,'کلاس‌بندی'!$D$5:$D$34,0)),"کد کلاس نامعتبر")) | K9: =IF(I9="","",IFERROR(INDEX('کلاس‌بندی'!$F$5:$F$34,MATCH(I9,'کلاس‌بندی'!$D$5:$D$34,0)),"")) | L9: =IF(COUNTA(C9:I9)=0,"",IF(AND(LEN(C9)=10,D9<>"",E9<>"",F9<>"",G9<>"",H9<>"",I9<>""),"کامل","ناقص"))
A10: 6 | B10: 6 | J10: =IF(I10="","",IFERROR(INDEX('کلاس‌بندی'!$E$5:$E$34,MATCH(I10,'کلاس‌بندی'!$D$5:$D$34,0)),"کد کلاس نامعتبر")) | K10: =IF(I10="","",IFERROR(INDEX('کلاس‌بندی'!$F$5:$F$34,MATCH(I10,'کلاس‌بندی'!$D$5:$D$34,0)),"")) | L10: =IF(COUNTA(C10:I10)=0,"",IF(AND(LEN(C10)=10,D10<>"",E10<>"",F10<>"",G10<>"",H10<>"",I10<>""),"کامل","ناقص"))
A11: 7 | B11: 7 | J11: =IF(I11="","",IFERROR(INDEX('کلاس‌بندی'!$E$5:$E$34,MATCH(I11,'کلاس‌بندی'!$D$5:$D$34,0)),"کد کلاس نامعتبر")) | K11: =IF(I11="","",IFERROR(INDEX('کلاس‌بندی'!$F$5:$F$34,MATCH(I11,'کلاس‌بندی'!$D$5:$D$34,0)),"")) | L11: =IF(COUNTA(C11:I11)=0,"",IF(AND(LEN(C11)=10,D11<>"",E11<>"",F11<>"",G11<>"",H11<>"",I11<>""),"کامل","ناقص"))
A12: 8 | B12: 8 | J12: =IF(I12="","",IFERROR(INDEX('کلاس‌بندی'!$E$5:$E$34,MATCH(I12,'کلاس‌بندی'!$D$5:$D$34,0)),"کد کلاس نامعتبر")) | K12: =IF(I12="","",IFERROR(INDEX('کلاس‌بندی'!$F$5:$F$34,MATCH(I12,'کلاس‌بندی'!$D$5:$D$34,0)),"")) | L12: =IF(COUNTA(C12:I12)=0,"",IF(AND(LEN(C12)=10,D12<>"",E12<>"",F12<>"",G12<>"",H12<>"",I12<>""),"کامل","ناقص"))
A13: 9 | B13: 9 | J13: =IF(I13="","",IFERROR(INDEX('کلاس‌بندی'!$E$5:$E$34,MATCH(I13,'کلاس‌بندی'!$D$5:$D$34,0)),"کد کلاس نامعتبر")) | K13: =IF(I13="","",IFERROR(INDEX('کلاس‌بندی'!$F$5:$F$34,MATCH(I13,'کلاس‌بندی'!$D$5:$D$34,0)),"")) | L13: =IF(COUNTA(C13:I13)=0,"",IF(AND(LEN(C13)=10,D13<>"",E13<>"",F13<>"",G13<>"",H13<>"",I13<>""),"کامل","ناقص"))
A14: 10 | B14: 10 | J14: =IF(I14="","",IFERROR(INDEX('کلاس‌بندی'!$E$5:$E$34,MATCH(I14,'کلاس‌بندی'!$D$5:$D$34,0)),"کد کلاس نامعتبر")) | K14: =IF(I14="","",IFERROR(INDEX('کلاس‌بندی'!$F$5:$F$34,MATCH(I14,'کلاس‌بندی'!$D$5:$D$34,0)),"")) | L14: =IF(COUNTA(C14:I14)=0,"",IF(AND(LEN(C14)=10,D14<>"",E14<>"",F14<>"",G14<>"",H14<>"",I14<>""),"کامل","ناقص"))
A15: 11 | B15: 11 | J15: =IF(I15="","",IFERROR(INDEX('کلاس‌بندی'!$E$5:$E$34,MATCH(I15,'کلاس‌بندی'!$D$5:$D$34,0)),"کد کلاس نامعتبر")) | K15: =IF(I15="","",IFERROR(INDEX('کلاس‌بندی'!$F$5:$F$34,MATCH(I15,'کلاس‌بندی'!$D$5:$D$34,0)),"")) | L15: =IF(COUNTA(C15:I15)=0,"",IF(AND(LEN(C15)=10,D15<>"",E15<>"",F15<>"",G15<>"",H15<>"",I15<>""),"کامل","ناقص"))
A16: 12 | B16: 12 | J16: =IF(I16="","",IFERROR(INDEX('کلاس‌بندی'!$E$5:$E$34,MATCH(I16,'کلاس‌بندی'!$D$5:$D$34,0)),"کد کلاس نامعتبر")) | K16: =IF(I16="","",IFERROR(INDEX('کلاس‌بندی'!$F$5:$F$34,MATCH(I16,'کلاس‌بندی'!$D$5:$D$34,0)),"")) | L16: =IF(COUNTA(C16:I16)=0,"",IF(AND(LEN(C16)=10,D16<>"",E16<>"",F16<>"",G16<>"",H16<>"",I16<>""),"کامل","ناقص"))
... A104: 100 | B104: 100 | J104: =IF(I104="","",IFERROR(INDEX('کلاس‌بندی'!$E$5:$E$34,MATCH(I104,'کلاس‌بندی'!$D$5:$D$34,0)),"کد کلاس نامعتبر")) | K104: =IF(I104="","",IFERROR(INDEX('کلاس‌بندی'!$F$5:$F$34,MATCH(I104,'کلاس‌بندی'!$D$5:$D$34,0)),"")) | L104: =IF(COUNTA(C104:I104)=0,"",IF(AND(LEN(C104)=10,D104<>"",E104<>"",F104<>"",G104<>"",H104<>"",I104<>""),"کامل","ناقص"))

Sheet ثبت اطلاعات
A1: ثبت اطلاعات ماهانه دانش‌آموزان
A2: فقط چهار ستون زرد امتیاز و ستون توضیحات را تکمیل کنید؛ اطلاعات هویتی و نتیجه به‌صورت خودکار ساخته می‌شوند.
G3: ورودی مدرسه | K3: محاسبه خودکار
A4: ردیف | B4: ماه | C4: کد محلی | D4: کد ملی | E4: نام و نام خانوادگی | F4: کد کلاس | G4: نمرات درسی (۰ تا ۵) | H4: انجام تکالیف (۰ تا ۵) | I4: مشارکت در کلاس (۰ تا ۵) | J4: حضور و غیاب (۰ تا ۵) | K4: امتیاز کلی (۰ تا ۲۰) | L4: سطح عملکرد | M4: شماره ماه | N4: درصد تکمیل | O4: توضیحات
A5: 1 | B5: تیر | C5: =IF('دانش‌آموزان'!E5="","",'دانش‌آموزان'!B5) | D5: =IF('دانش‌آموزان'!C5="","",'دانش‌آموزان'!C5) | E5: =IF('دانش‌آموزان'!E5="","",'دانش‌آموزان'!E5&" "&'دانش‌آموزان'!F5) | F5: =IF('دانش‌آموزان'!I5="","",'دانش‌آموزان'!I5) | K5: =IF(COUNT(G5:J5)=0,"",AVERAGE(G5:J5)*4) | L5: =IF(C5="","",IF(COUNT(G5:J5)=0,"",IF(COUNT(G5:J5)<4,"موقت - اطلاعات ناقص",IF(K5>=17,"عالی",IF(K5>=14,"خوب",IF(K5>=10,"متوسط","ضعیف")))))) | M5: 1 | N5: =IF(C5="","",COUNT(G5:J5)/4)
A6: 2 | B6: مرداد | C6: =IF('دانش‌آموزان'!E5="","",'دانش‌آموزان'!B5) | D6: =IF('دانش‌آموزان'!C5="","",'دانش‌آموزان'!C5) | E6: =IF('دانش‌آموزان'!E5="","",'دانش‌آموزان'!E5&" "&'دانش‌آموزان'!F5) | F6: =IF('دانش‌آموزان'!I5="","",'دانش‌آموزان'!I5) | K6: =IF(COUNT(G6:J6)=0,"",AVERAGE(G6:J6)*4) | L6: =IF(C6="","",IF(COUNT(G6:J6)=0,"",IF(COUNT(G6:J6)<4,"موقت - اطلاعات ناقص",IF(K6>=17,"عالی",IF(K6>=14,"خوب",IF(K6>=10,"متوسط","ضعیف")))))) | M6: 2 | N6: =IF(C6="","",COUNT(G6:J6)/4)
A7: 3 | B7: شهریور | C7: =IF('دانش‌آموزان'!E5="","",'دانش‌آموزان'!B5) | D7: =IF('دانش‌آموزان'!C5="","",'دانش‌آموزان'!C5) | E7: =IF('دانش‌آموزان'!E5="","",'دانش‌آموزان'!E5&" "&'دانش‌آموزان'!F5) | F7: =IF('دانش‌آموزان'!I5="","",'دانش‌آموزان'!I5) | K7: =IF(COUNT(G7:J7)=0,"",AVERAGE(G7:J7)*4) | L7: =IF(C7="","",IF(COUNT(G7:J7)=0,"",IF(COUNT(G7:J7)<4,"موقت - اطلاعات ناقص",IF(K7>=17,"عالی",IF(K7>=14,"خوب",IF(K7>=10,"متوسط","ضعیف")))))) | M7: 3 | N7: =IF(C7="","",COUNT(G7:J7)/4)
A8: 4 | B8: مهر | C8: =IF('دانش‌آموزان'!E5="","",'دانش‌آموزان'!B5) | D8: =IF('دانش‌آموزان'!C5="","",'دانش‌آموزان'!C5) | E8: =IF('دانش‌آموزان'!E5="","",'دانش‌آموزان'!E5&" "&'دانش‌آموزان'!F5) | F8: =IF('دانش‌آموزان'!I5="","",'دانش‌آموزان'!I5) | K8: =IF(COUNT(G8:J8)=0,"",AVERAGE(G8:J8)*4) | L8: =IF(C8="","",IF(COUNT(G8:J8)=0,"",IF(COUNT(G8:J8)<4,"موقت - اطلاعات ناقص",IF(K8>=17,"عالی",IF(K8>=14,"خوب",IF(K8>=10,"متوسط","ضعیف")))))) | M8: 4 | N8: =IF(C8="","",COUNT(G8:J8)/4)
A9: 5 | B9: آبان | C9: =IF('دانش‌آموزان'!E5="","",'دانش‌آموزان'!B5) | D9: =IF('دانش‌آموزان'!C5="","",'دانش‌آموزان'!C5) | E9: =IF('دانش‌آموزان'!E5="","",'دانش‌آموزان'!E5&" "&'دانش‌آموزان'!F5) | F9: =IF('دانش‌آموزان'!I5="","",'دانش‌آموزان'!I5) | K9: =IF(COUNT(G9:J9)=0,"",AVERAGE(G9:J9)*4) | L9: =IF(C9="","",IF(COUNT(G9:J9)=0,"",IF(COUNT(G9:J9)<4,"موقت - اطلاعات ناقص",IF(K9>=17,"عالی",IF(K9>=14,"خوب",IF(K9>=10,"متوسط","ضعیف")))))) | M9: 5 | N9: =IF(C9="","",COUNT(G9:J9)/4)
A10: 6 | B10: آذر | C10: =IF('دانش‌آموزان'!E5="","",'دانش‌آموزان'!B5) | D10: =IF('دانش‌آموزان'!C5="","",'دانش‌آموزان'!C5) | E10: =IF('دانش‌آموزان'!E5="","",'دانش‌آموزان'!E5&" "&'دانش‌آموزان'!F5) | F10: =IF('دانش‌آموزان'!I5="","",'دانش‌آموزان'!I5) | K10: =IF(COUNT(G10:J10)=0,"",AVERAGE(G10:J10)*4) | L10: =IF(C10="","",IF(COUNT(G10:J10)=0,"",IF(COUNT(G10:J10)<4,"موقت - اطلاعات ناقص",IF(K10>=17,"عالی",IF(K10>=14,"خوب",IF(K10>=10,"متوسط","ضعیف")))))) | M10: 6 | N10: =IF(C10="","",COUNT(G10:J10)/4)
A11: 7 | B11: دی | C11: =IF('دانش‌آموزان'!E5="","",'دانش‌آموزان'!B5) | D11: =IF('دانش‌آموزان'!C5="","",'دانش‌آموزان'!C5) | E11: =IF('دانش‌آموزان'!E5="","",'دانش‌آموزان'!E5&" "&'دانش‌آموزان'!F5) | F11: =IF('دانش‌آموزان'!I5="","",'دانش‌آموزان'!I5) | K11: =IF(COUNT(G11:J11)=0,"",AVERAGE(G11:J11)*4) | L11: =IF(C11="","",IF(COUNT(G11:J11)=0,"",IF(COUNT(G11:J11)<4,"موقت - اطلاعات ناقص",IF(K11>=17,"عالی",IF(K11>=14,"خوب",IF(K11>=10,"متوسط","ضعیف")))))) | M11: 7 | N11: =IF(C11="","",COUNT(G11:J11)/4)
A12: 8 | B12: بهمن | C12: =IF('دانش‌آموزان'!E5="","",'دانش‌آموزان'!B5) | D12: =IF('دانش‌آموزان'!C5="","",'دانش‌آموزان'!C5) | E12: =IF('دانش‌آموزان'!E5="","",'دانش‌آموزان'!E5&" "&'دانش‌آموزان'!F5) | F12: =IF('دانش‌آموزان'!I5="","",'دانش‌آموزان'!I5) | K12: =IF(COUNT(G12:J12)=0,"",AVERAGE(G12:J12)*4) | L12: =IF(C12="","",IF(COUNT(G12:J12)=0,"",IF(COUNT(G12:J12)<4,"موقت - اطلاعات ناقص",IF(K12>=17,"عالی",IF(K12>=14,"خوب",IF(K12>=10,"متوسط","ضعیف")))))) | M12: 8 | N12: =IF(C12="","",COUNT(G12:J12)/4)
A13: 9 | B13: اسفند | C13: =IF('دانش‌آموزان'!E5="","",'دانش‌آموزان'!B5) | D13: =IF('دانش‌آموزان'!C5="","",'دانش‌آموزان'!C5) | E13: =IF('دانش‌آموزان'!E5="","",'دانش‌آموزان'!E5&" "&'دانش‌آموزان'!F5) | F13: =IF('دانش‌آموزان'!I5="","",'دانش‌آموزان'!I5) | K13: =IF(COUNT(G13:J13)=0,"",AVERAGE(G13:J13)*4) | L13: =IF(C13="","",IF(COUNT(G13:J13)=0,"",IF(COUNT(G13:J13)<4,"موقت - اطلاعات ناقص",IF(K13>=17,"عالی",IF(K13>=14,"خوب",IF(K13>=10,"متوسط","ضعیف")))))) | M13: 9 | N13: =IF(C13="","",COUNT(G13:J13)/4)
A14: 10 | B14: فروردین | C14: =IF('دانش‌آموزان'!E5="","",'دانش‌آموزان'!B5) | D14: =IF('دانش‌آموزان'!C5="","",'دانش‌آموزان'!C5) | E14: =IF('دانش‌آموزان'!E5="","",'دانش‌آموزان'!E5&" "&'دانش‌آموزان'!F5) | F14: =IF('دانش‌آموزان'!I5="","",'دانش‌آموزان'!I5) | K14: =IF(COUNT(G14:J14)=0,"",AVERAGE(G14:J14)*4) | L14: =IF(C14="","",IF(COUNT(G14:J14)=0,"",IF(COUNT(G14:J14)<4,"موقت - اطلاعات ناقص",IF(K14>=17,"عالی",IF(K14>=14,"خوب",IF(K14>=10,"متوسط","ضعیف")))))) | M14: 10 | N14: =IF(C14="","",COUNT(G14:J14)/4)
A15: 11 | B15: اردیبهشت | C15: =IF('دانش‌آموزان'!E5="","",'دانش‌آموزان'!B5) | D15: =IF('دانش‌آموزان'!C5="","",'دانش‌آموزان'!C5) | E15: =IF('دانش‌آموزان'!E5="","",'دانش‌آموزان'!E5&" "&'دانش‌آموزان'!F5) | F15: =IF('دانش‌آموزان'!I5="","",'دانش‌آموزان'!I5) | K15: =IF(COUNT(G15:J15)=0,"",AVERAGE(G15:J15)*4) | L15: =IF(C15="","",IF(COUNT(G15:J15)=0,"",IF(COUNT(G15:J15)<4,"موقت - اطلاعات ناقص",IF(K15>=17,"عالی",IF(K15>=14,"خوب",IF(K15>=10,"متوسط","ضعیف")))))) | M15: 11 | N15: =IF(C15="","",COUNT(G15:J15)/4)
A16: 12 | B16: خرداد | C16: =IF('دانش‌آموزان'!E5="","",'دانش‌آموزان'!B5) | D16: =IF('دانش‌آموزان'!C5="","",'دانش‌آموزان'!C5) | E16: =IF('دانش‌آموزان'!E5="","",'دانش‌آموزان'!E5&" "&'دانش‌آموزان'!F5) | F16: =IF('دانش‌آموزان'!I5="","",'دانش‌آموزان'!I5) | K16: =IF(COUNT(G16:J16)=0,"",AVERAGE(G16:J16)*4) | L16: =IF(C16="","",IF(COUNT(G16:J16)=0,"",IF(COUNT(G16:J16)<4,"موقت - اطلاعات ناقص",IF(K16>=17,"عالی",IF(K16>=14,"خوب",IF(K16>=10,"متوسط","ضعیف")))))) | M16: 12 | N16: =IF(C16="","",COUNT(G16:J16)/4)
A17: 13 | B17: تیر | C17: =IF('دانش‌آموزان'!E6="","",'دانش‌آموزان'!B6) | D17: =IF('دانش‌آموزان'!C6="","",'دانش‌آموزان'!C6) | E17: =IF('دانش‌آموزان'!E6="","",'دانش‌آموزان'!E6&" "&'دانش‌آموزان'!F6) | F17: =IF('دانش‌آموزان'!I6="","",'دانش‌آموزان'!I6) | K17: =IF(COUNT(G17:J17)=0,"",AVERAGE(G17:J17)*4) | L17: =IF(C17="","",IF(COUNT(G17:J17)=0,"",IF(COUNT(G17:J17)<4,"موقت - اطلاعات ناقص",IF(K17>=17,"عالی",IF(K17>=14,"خوب",IF(K17>=10,"متوسط","ضعیف")))))) | M17: 1 | N17: =IF(C17="","",COUNT(G17:J17)/4)
A18: 14 | B18: مرداد | C18: =IF('دانش‌آموزان'!E6="","",'دانش‌آموزان'!B6) | D18: =IF('دانش‌آموزان'!C6="","",'دانش‌آموزان'!C6) | E18: =IF('دانش‌آموزان'!E6="","",'دانش‌آموزان'!E6&" "&'دانش‌آموزان'!F6) | F18: =IF('دانش‌آموزان'!I6="","",'دانش‌آموزان'!I6) | K18: =IF(COUNT(G18:J18)=0,"",AVERAGE(G18:J18)*4) | L18: =IF(C18="","",IF(COUNT(G18:J18)=0,"",IF(COUNT(G18:J18)<4,"موقت - اطلاعات ناقص",IF(K18>=17,"عالی",IF(K18>=14,"خوب",IF(K18>=10,"متوسط","ضعیف")))))) | M18: 2 | N18: =IF(C18="","",COUNT(G18:J18)/4)
A19: 15 | B19: شهریور | C19: =IF('دانش‌آموزان'!E6="","",'دانش‌آموزان'!B6) | D19: =IF('دانش‌آموزان'!C6="","",'دانش‌آموزان'!C6) | E19: =IF('دانش‌آموزان'!E6="","",'دانش‌آموزان'!E6&" "&'دانش‌آموزان'!F6) | F19: =IF('دانش‌آموزان'!I6="","",'دانش‌آموزان'!I6) | K19: =IF(COUNT(G19:J19)=0,"",AVERAGE(G19:J19)*4) | L19: =IF(C19="","",IF(COUNT(G19:J19)=0,"",IF(COUNT(G19:J19)<4,"موقت - اطلاعات ناقص",IF(K19>=17,"عالی",IF(K19>=14,"خوب",IF(K19>=10,"متوسط","ضعیف")))))) | M19: 3 | N19: =IF(C19="","",COUNT(G19:J19)/4)
A20: 16 | B20: مهر | C20: =IF('دانش‌آموزان'!E6="","",'دانش‌آموزان'!B6) | D20: =IF('دانش‌آموزان'!C6="","",'دانش‌آموزان'!C6) | E20: =IF('دانش‌آموزان'!E6="","",'دانش‌آموزان'!E6&" "&'دانش‌آموزان'!F6) | F20: =IF('دانش‌آموزان'!I6="","",'دانش‌آموزان'!I6) | K20: =IF(COUNT(G20:J20)=0,"",AVERAGE(G20:J20)*4) | L20: =IF(C20="","",IF(COUNT(G20:J20)=0,"",IF(COUNT(G20:J20)<4,"موقت - اطلاعات ناقص",IF(K20>=17,"عالی",IF(K20>=14,"خوب",IF(K20>=10,"متوسط","ضعیف")))))) | M20: 4 | N20: =IF(C20="","",COUNT(G20:J20)/4)
A21: 17 | B21: آبان | C21: =IF('دانش‌آموزان'!E6="","",'دانش‌آموزان'!B6) | D21: =IF('دانش‌آموزان'!C6="","",'دانش‌آموزان'!C6) | E21: =IF('دانش‌آموزان'!E6="","",'دانش‌آموزان'!E6&" "&'دانش‌آموزان'!F6) | F21: =IF('دانش‌آموزان'!I6="","",'دانش‌آموزان'!I6) | K21: =IF(COUNT(G21:J21)=0,"",AVERAGE(G21:J21)*4) | L21: =IF(C21="","",IF(COUNT(G21:J21)=0,"",IF(COUNT(G21:J21)<4,"موقت - اطلاعات ناقص",IF(K21>=17,"عالی",IF(K21>=14,"خوب",IF(K21>=10,"متوسط","ضعیف")))))) | M21: 5 | N21: =IF(C21="","",COUNT(G21:J21)/4)
A22: 18 | B22: آذر | C22: =IF('دانش‌آموزان'!E6="","",'دانش‌آموزان'!B6) | D22: =IF('دانش‌آموزان'!C6="","",'دانش‌آموزان'!C6) | E22: =IF('دانش‌آموزان'!E6="","",'دانش‌آموزان'!E6&" "&'دانش‌آموزان'!F6) | F22: =IF('دانش‌آموزان'!I6="","",'دانش‌آموزان'!I6) | K22: =IF(COUNT(G22:J22)=0,"",AVERAGE(G22:J22)*4) | L22: =IF(C22="","",IF(COUNT(G22:J22)=0,"",IF(COUNT(G22:J22)<4,"موقت - اطلاعات ناقص",IF(K22>=17,"عالی",IF(K22>=14,"خوب",IF(K22>=10,"متوسط","ضعیف")))))) | M22: 6 | N22: =IF(C22="","",COUNT(G22:J22)/4)
A23: 19 | B23: دی | C23: =IF('دانش‌آموزان'!E6="","",'دانش‌آموزان'!B6) | D23: =IF('دانش‌آموزان'!C6="","",'دانش‌آموزان'!C6) | E23: =IF('دانش‌آموزان'!E6="","",'دانش‌آموزان'!E6&" "&'دانش‌آموزان'!F6) | F23: =IF('دانش‌آموزان'!I6="","",'دانش‌آموزان'!I6) | K23: =IF(COUNT(G23:J23)=0,"",AVERAGE(G23:J23)*4) | L23: =IF(C23="","",IF(COUNT(G23:J23)=0,"",IF(COUNT(G23:J23)<4,"موقت - اطلاعات ناقص",IF(K23>=17,"عالی",IF(K23>=14,"خوب",IF(K23>=10,"متوسط","ضعیف")))))) | M23: 7 | N23: =IF(C23="","",COUNT(G23:J23)/4)
A24: 20 | B24: بهمن | C24: =IF('دانش‌آموزان'!E6="","",'دانش‌آموزان'!B6) | D24: =IF('دانش‌آموزان'!C6="","",'دانش‌آموزان'!C6) | E24: =IF('دانش‌آموزان'!E6="","",'دانش‌آموزان'!E6&" "&'دانش‌آموزان'!F6) | F24: =IF('دانش‌آموزان'!I6="","",'دانش‌آموزان'!I6) | K24: =IF(COUNT(G24:J24)=0,"",AVERAGE(G24:J24)*4) | L24: =IF(C24="","",IF(COUNT(G24:J24)=0,"",IF(COUNT(G24:J24)<4,"موقت - اطلاعات ناقص",IF(K24>=17,"عالی",IF(K24>=14,"خوب",IF(K24>=10,"متوسط","ضعیف")))))) | M24: 8 | N24: =IF(C24="","",COUNT(G24:J24)/4)
A25: 21 | B25: اسفند | C25: =IF('دانش‌آموزان'!E6="","",'دانش‌آموزان'!B6) | D25: =IF('دانش‌آموزان'!C6="","",'دانش‌آموزان'!C6) | E25: =IF('دانش‌آموزان'!E6="","",'دانش‌آموزان'!E6&" "&'دانش‌آموزان'!F6) | F25: =IF('دانش‌آموزان'!I6="","",'دانش‌آموزان'!I6) | K25: =IF(COUNT(G25:J25)=0,"",AVERAGE(G25:J25)*4) | L25: =IF(C25="","",IF(COUNT(G25:J25)=0,"",IF(COUNT(G25:J25)<4,"موقت - اطلاعات ناقص",IF(K25>=17,"عالی",IF(K25>=14,"خوب",IF(K25>=10,"متوسط","ضعیف")))))) | M25: 9 | N25: =IF(C25="","",COUNT(G25:J25)/4)
A26: 22 | B26: فروردین | C26: =IF('دانش‌آموزان'!E6="","",'دانش‌آموزان'!B6) | D26: =IF('دانش‌آموزان'!C6="","",'دانش‌آموزان'!C6) | E26: =IF('دانش‌آموزان'!E6="","",'دانش‌آموزان'!E6&" "&'دانش‌آموزان'!F6) | F26: =IF('دانش‌آموزان'!I6="","",'دانش‌آموزان'!I6) | K26: =IF(COUNT(G26:J26)=0,"",AVERAGE(G26:J26)*4) | L26: =IF(C26="","",IF(COUNT(G26:J26)=0,"",IF(COUNT(G26:J26)<4,"موقت - اطلاعات ناقص",IF(K26>=17,"عالی",IF(K26>=14,"خوب",IF(K26>=10,"متوسط","ضعیف")))))) | M26: 10 | N26: =IF(C26="","",COUNT(G26:J26)/4)
A27: 23 | B27: اردیبهشت | C27: =IF('دانش‌آموزان'!E6="","",'دانش‌آموزان'!B6) | D27: =IF('دانش‌آموزان'!C6="","",'دانش‌آموزان'!C6) | E27: =IF('دانش‌آموزان'!E6="","",'دانش‌آموزان'!E6&" "&'دانش‌آموزان'!F6) | F27: =IF('دانش‌آموزان'!I6="","",'دانش‌آموزان'!I6) | K27: =IF(COUNT(G27:J27)=0,"",AVERAGE(G27:J27)*4) | L27: =IF(C27="","",IF(COUNT(G27:J27)=0,"",IF(COUNT(G27:J27)<4,"موقت - اطلاعات ناقص",IF(K27>=17,"عالی",IF(K27>=14,"خوب",IF(K27>=10,"متوسط","ضعیف")))))) | M27: 11 | N27: =IF(C27="","",COUNT(G27:J27)/4)
A28: 24 | B28: خرداد | C28: =IF('دانش‌آموزان'!E6="","",'دانش‌آموزان'!B6) | D28: =IF('دانش‌آموزان'!C6="","",'دانش‌آموزان'!C6) | E28: =IF('دانش‌آموزان'!E6="","",'دانش‌آموزان'!E6&" "&'دانش‌آموزان'!F6) | F28: =IF('دانش‌آموزان'!I6="","",'دانش‌آموزان'!I6) | K28: =IF(COUNT(G28:J28)=0,"",AVERAGE(G28:J28)*4) | L28: =IF(C28="","",IF(COUNT(G28:J28)=0,"",IF(COUNT(G28:J28)<4,"موقت - اطلاعات ناقص",IF(K28>=17,"عالی",IF(K28>=14,"خوب",IF(K28>=10,"متوسط","ضعیف")))))) | M28: 12 | N28: =IF(C28="","",COUNT(G28:J28)/4)
A29: 25 | B29: تیر | C29: =IF('دانش‌آموزان'!E7="","",'دانش‌آموزان'!B7) | D29: =IF('دانش‌آموزان'!C7="","",'دانش‌آموزان'!C7) | E29: =IF('دانش‌آموزان'!E7="","",'دانش‌آموزان'!E7&" "&'دانش‌آموزان'!F7) | F29: =IF('دانش‌آموزان'!I7="","",'دانش‌آموزان'!I7) | K29: =IF(COUNT(G29:J29)=0,"",AVERAGE(G29:J29)*4) | L29: =IF(C29="","",IF(COUNT(G29:J29)=0,"",IF(COUNT(G29:J29)<4,"موقت - اطلاعات ناقص",IF(K29>=17,"عالی",IF(K29>=14,"خوب",IF(K29>=10,"متوسط","ضعیف")))))) | M29: 1 | N29: =IF(C29="","",COUNT(G29:J29)/4)
A30: 26 | B30: مرداد | C30: =IF('دانش‌آموزان'!E7="","",'دانش‌آموزان'!B7) | D30: =IF('دانش‌آموزان'!C7="","",'دانش‌آموزان'!C7) | E30: =IF('دانش‌آموزان'!E7="","",'دانش‌آموزان'!E7&" "&'دانش‌آموزان'!F7) | F30: =IF('دانش‌آموزان'!I7="","",'دانش‌آموزان'!I7) | K30: =IF(COUNT(G30:J30)=0,"",AVERAGE(G30:J30)*4) | L30: =IF(C30="","",IF(COUNT(G30:J30)=0,"",IF(COUNT(G30:J30)<4,"موقت - اطلاعات ناقص",IF(K30>=17,"عالی",IF(K30>=14,"خوب",IF(K30>=10,"متوسط","ضعیف")))))) | M30: 2 | N30: =IF(C30="","",COUNT(G30:J30)/4)
A31: 27 | B31: شهریور | C31: =IF('دانش‌آموزان'!E7="","",'دانش‌آموزان'!B7) | D31: =IF('دانش‌آموزان'!C7="","",'دانش‌آموزان'!C7) | E31: =IF('دانش‌آموزان'!E7="","",'دانش‌آموزان'!E7&" "&'دانش‌آموزان'!F7) | F31: =IF('دانش‌آموزان'!I7="","",'دانش‌آموزان'!I7) | K31: =IF(COUNT(G31:J31)=0,"",AVERAGE(G31:J31)*4) | L31: =IF(C31="","",IF(COUNT(G31:J31)=0,"",IF(COUNT(G31:J31)<4,"موقت - اطلاعات ناقص",IF(K31>=17,"عالی",IF(K31>=14,"خوب",IF(K31>=10,"متوسط","ضعیف")))))) | M31: 3 | N31: =IF(C31="","",COUNT(G31:J31)/4)
A32: 28 | B32: مهر | C32: =IF('دانش‌آموزان'!E7="","",'دانش‌آموزان'!B7) | D32: =IF('دانش‌آموزان'!C7="","",'دانش‌آموزان'!C7) | E32: =IF('دانش‌آموزان'!E7="","",'دانش‌آموزان'!E7&" "&'دانش‌آموزان'!F7) | F32: =IF('دانش‌آموزان'!I7="","",'دانش‌آموزان'!I7) | K32: =IF(COUNT(G32:J32)=0,"",AVERAGE(G32:J32)*4) | L32: =IF(C32="","",IF(COUNT(G32:J32)=0,"",IF(COUNT(G32:J32)<4,"موقت - اطلاعات ناقص",IF(K32>=17,"عالی",IF(K32>=14,"خوب",IF(K32>=10,"متوسط","ضعیف")))))) | M32: 4 | N32: =IF(C32="","",COUNT(G32:J32)/4)
A33: 29 | B33: آبان | C33: =IF('دانش‌آموزان'!E7="","",'دانش‌آموزان'!B7) | D33: =IF('دانش‌آموزان'!C7="","",'دانش‌آموزان'!C7) | E33: =IF('دانش‌آموزان'!E7="","",'دانش‌آموزان'!E7&" "&'دانش‌آموزان'!F7) | F33: =IF('دانش‌آموزان'!I7="","",'دانش‌آموزان'!I7) | K33: =IF(COUNT(G33:J33)=0,"",AVERAGE(G33:J33)*4) | L33: =IF(C33="","",IF(COUNT(G33:J33)=0,"",IF(COUNT(G33:J33)<4,"موقت - اطلاعات ناقص",IF(K33>=17,"عالی",IF(K33>=14,"خوب",IF(K33>=10,"متوسط","ضعیف")))))) | M33: 5 | N33: =IF(C33="","",COUNT(G33:J33)/4)
A34: 30 | B34: آذر | C34: =IF('دانش‌آموزان'!E7="","",'دانش‌آموزان'!B7) | D34: =IF('دانش‌آموزان'!C7="","",'دانش‌آموزان'!C7) | E34: =IF('دانش‌آموزان'!E7="","",'دانش‌آموزان'!E7&" "&'دانش‌آموزان'!F7) | F34: =IF('دانش‌آموزان'!I7="","",'دانش‌آموزان'!I7) | K34: =IF(COUNT(G34:J34)=0,"",AVERAGE(G34:J34)*4) | L34: =IF(C34="","",IF(COUNT(G34:J34)=0,"",IF(COUNT(G34:J34)<4,"موقت - اطلاعات ناقص",IF(K34>=17,"عالی",IF(K34>=14,"خوب",IF(K34>=10,"متوسط","ضعیف")))))) | M34: 6 | N34: =IF(C34="","",COUNT(G34:J34)/4)
A35: 31 | B35: دی | C35: =IF('دانش‌آموزان'!E7="","",'دانش‌آموزان'!B7) | D35: =IF('دانش‌آموزان'!C7="","",'دانش‌آموزان'!C7) | E35: =IF('دانش‌آموزان'!E7="","",'دانش‌آموزان'!E7&" "&'دانش‌آموزان'!F7) | F35: =IF('دانش‌آموزان'!I7="","",'دانش‌آموزان'!I7) | K35: =IF(COUNT(G35:J35)=0,"",AVERAGE(G35:J35)*4) | L35: =IF(C35="","",IF(COUNT(G35:J35)=0,"",IF(COUNT(G35:J35)<4,"موقت - اطلاعات ناقص",IF(K35>=17,"عالی",IF(K35>=14,"خوب",IF(K35>=10,"متوسط","ضعیف")))))) | M35: 7 | N35: =IF(C35="","",COUNT(G35:J35)/4)
A36: 32 | B36: بهمن | C36: =IF('دانش‌آموزان'!E7="","",'دانش‌آموزان'!B7) | D36: =IF('دانش‌آموزان'!C7="","",'دانش‌آموزان'!C7) | E36: =IF('دانش‌آموزان'!E7="","",'دانش‌آموزان'!E7&" "&'دانش‌آموزان'!F7) | F36: =IF('دانش‌آموزان'!I7="","",'دانش‌آموزان'!I7) | K36: =IF(COUNT(G36:J36)=0,"",AVERAGE(G36:J36)*4) | L36: =IF(C36="","",IF(COUNT(G36:J36)=0,"",IF(COUNT(G36:J36)<4,"موقت - اطلاعات ناقص",IF(K36>=17,"عالی",IF(K36>=14,"خوب",IF(K36>=10,"متوسط","ضعیف")))))) | M36: 8 | N36: =IF(C36="","",COUNT(G36:J36)/4)
A37: 33 | B37: اسفند | C37: =IF('دانش‌آموزان'!E7="","",'دانش‌آموزان'!B7) | D37: =IF('دانش‌آموزان'!C7="","",'دانش‌آموزان'!C7) | E37: =IF('دانش‌آموزان'!E7="","",'دانش‌آموزان'!E7&" "&'دانش‌آموزان'!F7) | F37: =IF('دانش‌آموزان'!I7="","",'دانش‌آموزان'!I7) | K37: =IF(COUNT(G37:J37)=0,"",AVERAGE(G37:J37)*4) | L37: =IF(C37="","",IF(COUNT(G37:J37)=0,"",IF(COUNT(G37:J37)<4,"موقت - اطلاعات ناقص",IF(K37>=17,"عالی",IF(K37>=14,"خوب",IF(K37>=10,"متوسط","ضعیف")))))) | M37: 9 | N37: =IF(C37="","",COUNT(G37:J37)/4)
A38: 34 | B38: فروردین | C38: =IF('دانش‌آموزان'!E7="","",'دانش‌آموزان'!B7) | D38: =IF('دانش‌آموزان'!C7="","",'دانش‌آموزان'!C7) | E38: =IF('دانش‌آموزان'!E7="","",'دانش‌آموزان'!E7&" "&'دانش‌آموزان'!F7) | F38: =IF('دانش‌آموزان'!I7="","",'دانش‌آموزان'!I7) | K38: =IF(COUNT(G38:J38)=0,"",AVERAGE(G38:J38)*4) | L38: =IF(C38="","",IF(COUNT(G38:J38)=0,"",IF(COUNT(G38:J38)<4,"موقت - اطلاعات ناقص",IF(K38>=17,"عالی",IF(K38>=14,"خوب",IF(K38>=10,"متوسط","ضعیف")))))) | M38: 10 | N38: =IF(C38="","",COUNT(G38:J38)/4)
A39: 35 | B39: اردیبهشت | C39: =IF('دانش‌آموزان'!E7="","",'دانش‌آموزان'!B7) | D39: =IF('دانش‌آموزان'!C7="","",'دانش‌آموزان'!C7) | E39: =IF('دانش‌آموزان'!E7="","",'دانش‌آموزان'!E7&" "&'دانش‌آموزان'!F7) | F39: =IF('دانش‌آموزان'!I7="","",'دانش‌آموزان'!I7) | K39: =IF(COUNT(G39:J39)=0,"",AVERAGE(G39:J39)*4) | L39: =IF(C39="","",IF(COUNT(G39:J39)=0,"",IF(COUNT(G39:J39)<4,"موقت - اطلاعات ناقص",IF(K39>=17,"عالی",IF(K39>=14,"خوب",IF(K39>=10,"متوسط","ضعیف")))))) | M39: 11 | N39: =IF(C39="","",COUNT(G39:J39)/4)
A40: 36 | B40: خرداد | C40: =IF('دانش‌آموزان'!E7="","",'دانش‌آموزان'!B7) | D40: =IF('دانش‌آموزان'!C7="","",'دانش‌آموزان'!C7) | E40: =IF('دانش‌آموزان'!E7="","",'دانش‌آموزان'!E7&" "&'دانش‌آموزان'!F7) | F40: =IF('دانش‌آموزان'!I7="","",'دانش‌آموزان'!I7) | K40: =IF(COUNT(G40:J40)=0,"",AVERAGE(G40:J40)*4) | L40: =IF(C40="","",IF(COUNT(G40:J40)=0,"",IF(COUNT(G40:J40)<4,"موقت - اطلاعات ناقص",IF(K40>=17,"عالی",IF(K40>=14,"خوب",IF(K40>=10,"متوسط","ضعیف")))))) | M40: 12 | N40: =IF(C40="","",COUNT(G40:J40)/4)
...
