Workbook

Sheet راهنما
A1: قالب جامع جمع‌آوری اطلاعات مدرسه
A2: این فایل برای دریافت یک‌جای کلاس‌بندی، فهرست دانش‌آموزان و ارزیابی ماهانه طراحی شده است. فقط خانه‌های زرد را تکمیل کنید.
A4: مرحله | B4: شیت | C4: کار لازم | D4: فیلدهای کلیدی | E4: کنترل فایل | F4: رنگ ورودی | G4: خروجی | H4: نکته مهم
A5: 1 | B5: کلاس‌بندی | C5: کلاس‌های مدرسه را وارد کنید. | D5: کد مدرسه، سال تحصیلی، کد و نام کلاس، پایه، ظرفیت | E5: کد کلاس تکراری نباشد. | F5: زرد | G5: فهرست کلاس‌ها | H5: کد کلاس باید در تمام شیت‌ها یکسان باشد.
A6: 2 | B6: دانش‌آموزان | C6: مشخصات هر دانش‌آموز و کلاس او را ثبت کنید. | D6: کد ملی، شماره دانش‌آموزی، نام، نام خانوادگی، جنسیت، تاریخ تولد، کد کلاس | E6: وضعیت کامل/ناقص خودکار است. | F6: زرد | G6: فهرست دانش‌آموزان | H6: کد ملی و شماره دانش‌آموزی را به‌صورت متن وارد کنید؛ صفر ابتدایی حذف نشود.
A7: 3 | B7: ثبت اطلاعات | C7: برای هر دانش‌آموز در هر ماه، ۴۶ شاخص را از ۰ تا ۵ نمره دهید. | D7: ماه، ۴۶ نمره، توضیحات | E7: درصد تکمیل و امتیازها خودکار است. | F7: زرد | G7: ارزیابی ماهانه | H7: نتیجه فقط با تکمیل هر ۴۶ شاخص نهایی می‌شود.
A8: 4 | B8: گزارش و داشبورد | C8: پس از ورود اطلاعات، گزارش‌ها را مشاهده کنید. | D8: روند، میانگین، رتبه واقعی، قوی‌ترین و ضعیف‌ترین حوزه | E8: محاسبه خودکار | F8: آبی/سبز | G8: تحلیل قابل ارائه | H8: رتبه فقط میان دانش‌آموزان دارای حداقل یک ارزیابی نهایی محاسبه می‌شود.
A10: مقیاس نمره‌دهی شاخص‌ها: ۰ = مشاهده نشده / بسیار ضعیف، ۱ = ضعیف، ۲ = نیازمند بهبود، ۳ = قابل قبول، ۴ = خوب، ۵ = بسیار خوب
A12: ترتیب ماه‌ها در فایل: تیر تا خرداد. خانه‌های خاکستری و آبی دارای فرمول هستند و نباید ویرایش شوند.

Sheet کلاس‌بندی
A1: کلاس‌بندی مدرسه
A2: هر کلاس را فقط یک‌بار وارد کنید. ظرفیت ثبت‌شده و تعداد دانش‌آموزان تخصیص‌یافته به‌صورت خودکار مقایسه می‌شوند.
A4: ردیف | B4: کد مدرسه | C4: سال تحصیلی | D4: کد کلاس | E4: نام کلاس | F4: پایه تحصیلی | G4: ظرفیت | H4: تعداد ثبت‌شده | I4: وضعیت
A5: 1 | B5: 95114129 | C5: 1405-1406 | D5: 901 | E5: فردوسی 1 | F5: نهم | G5: 35 | H5: =IF(D5="","",COUNTIF(دانش‌آموزان!$I$5:$I$104,D5)) -> 32 | I5: =IF(D5="","",IF(COUNTIF($D$5:$D$34,D5)>1,"کد تکراری",IF(H5>G5,"بیش از ظرفیت","معتبر"))) -> معتبر
A6: 2
A7: 3
A8: 4
A9: 5
A10: 6
A11: 7
A12: 8
A13: 9
A14: 10
A15: 11
A16: 12
A17: 13
... A34: 30

Sheet دانش‌آموزان
A1: فهرست دانش‌آموزان
A2: برای هر دانش‌آموز یک ردیف تکمیل کنید. کد محلی ۱ تا ۱۰۰ از قبل ساخته شده و مبنای گزارش‌های همین فایل است.
A4: ردیف | B4: کد محلی | C4: کد ملی | D4: شماره دانش‌آموزی | E4: نام | F4: نام خانوادگی | G4: جنسیت | H4: تاریخ تولد | I4: کد کلاس | J4: نام کلاس | K4: پایه | L4: وضعیت اطلاعات
A5: 1 | B5: 1 | C5: 0960326367 | D5: 0960326367 | E5: نيما | F5: اسكندري تربقان | G5: پسر | H5: 1390/10/25 | I5: 901 | J5: فردوسی 1 | K5: =IF(I5="","",IFERROR(INDEX(کلاس‌بندی!$F$5:$F$34,MATCH(I5,کلاس‌بندی!$D$5:$D$34,0)),"")) -> نهم | L5: =IF(COUNTA(C5:I5)=0,"",IF(AND(LEN(C5)=10,D5<>"",E5<>"",F5<>"",G5<>"",H5<>"",I5<>""),"کامل","ناقص")) -> کامل
A6: 2 | B6: 2 | C6: 0980506328 | D6: 0980506328 | E6: اميررضا | F6: اميري | G6: پسر | H6: 1391/07/01 | I6: 901 | J6: فردوسی 1 | K6: =IF(I6="","",IFERROR(INDEX(کلاس‌بندی!$F$5:$F$34,MATCH(I6,کلاس‌بندی!$D$5:$D$34,0)),"")) -> نهم | L6: =IF(COUNTA(C6:I6)=0,"",IF(AND(LEN(C6)=10,D6<>"",E6<>"",F6<>"",G6<>"",H6<>"",I6<>""),"کامل","ناقص")) -> کامل
A7: 3 | B7: 3 | C7: 0960300473 | D7: 0960300473 | E7: محمدامين | F7: باقري | G7: پسر | H7: 1390/09/08 | I7: 901 | J7: فردوسی 1 | K7: =IF(I7="","",IFERROR(INDEX(کلاس‌بندی!$F$5:$F$34,MATCH(I7,کلاس‌بندی!$D$5:$D$34,0)),"")) -> نهم | L7: =IF(COUNTA(C7:I7)=0,"",IF(AND(LEN(C7)=10,D7<>"",E7<>"",F7<>"",G7<>"",H7<>"",I7<>""),"کامل","ناقص")) -> کامل
A8: 4 | B8: 4 | C8: 0960412271 | D8: 0960412271 | E8: اميرحيدر | F8: ترابي | G8: پسر | H8: 1391/04/13 | I8: 901 | J8: فردوسی 1 | K8: =IF(I8="","",IFERROR(INDEX(کلاس‌بندی!$F$5:$F$34,MATCH(I8,کلاس‌بندی!$D$5:$D$34,0)),"")) -> نهم | L8: =IF(COUNTA(C8:I8)=0,"",IF(AND(LEN(C8)=10,D8<>"",E8<>"",F8<>"",G8<>"",H8<>"",I8<>""),"کامل","ناقص")) -> کامل
A9: 5 | B9: 5 | C9: 0960309799 | D9: 0960309799 | E9: سيدآرمان | F9: تقوي | G9: پسر | H9: 1390/08/08 | I9: 901 | J9: فردوسی 1 | K9: =IF(I9="","",IFERROR(INDEX(کلاس‌بندی!$F$5:$F$34,MATCH(I9,کلاس‌بندی!$D$5:$D$34,0)),"")) -> نهم | L9: =IF(COUNTA(C9:I9)=0,"",IF(AND(LEN(C9)=10,D9<>"",E9<>"",F9<>"",G9<>"",H9<>"",I9<>""),"کامل","ناقص")) -> کامل
A10: 6 | B10: 6 | C10: 0980449561 | D10: 0980449561 | E10: كيان | F10: تقي پور حصاري | G10: پسر | H10: 1391/03/30 | I10: 901 | J10: فردوسی 1 | K10: =IF(I10="","",IFERROR(INDEX(کلاس‌بندی!$F$5:$F$34,MATCH(I10,کلاس‌بندی!$D$5:$D$34,0)),"")) -> نهم | L10: =IF(COUNTA(C10:I10)=0,"",IF(AND(LEN(C10)=10,D10<>"",E10<>"",F10<>"",G10<>"",H10<>"",I10<>""),"کامل","ناقص")) -> کامل
A11: 7 | B11: 7 | C11: 0970629982 | D11: 0970629982 | E11: اميررضا | F11: جاجرمي | G11: پسر | H11: 1391/06/02 | I11: 901 | J11: فردوسی 1 | K11: =IF(I11="","",IFERROR(INDEX(کلاس‌بندی!$F$5:$F$34,MATCH(I11,کلاس‌بندی!$D$5:$D$34,0)),"")) -> نهم | L11: =IF(COUNTA(C11:I11)=0,"",IF(AND(LEN(C11)=10,D11<>"",E11<>"",F11<>"",G11<>"",H11<>"",I11<>""),"کامل","ناقص")) -> کامل
A12: 8 | B12: 8 | C12: 0960433929 | D12: 0960433929 | E12: سپهر | F12: جمشيديان مجاور | G12: پسر | H12: 1391/05/22 | I12: 901 | J12: فردوسی 1 | K12: =IF(I12="","",IFERROR(INDEX(کلاس‌بندی!$F$5:$F$34,MATCH(I12,کلاس‌بندی!$D$5:$D$34,0)),"")) -> نهم | L12: =IF(COUNTA(C12:I12)=0,"",IF(AND(LEN(C12)=10,D12<>"",E12<>"",F12<>"",G12<>"",H12<>"",I12<>""),"کامل","ناقص")) -> کامل
A13: 9 | B13: 9 | C13: 0960426116 | D13: 0960426116 | E13: محمدحسين | F13: حسن پورويراني | G13: پسر | H13: 1391/05/08 | I13: 901 | J13: فردوسی 1 | K13: =IF(I13="","",IFERROR(INDEX(کلاس‌بندی!$F$5:$F$34,MATCH(I13,کلاس‌بندی!$D$5:$D$34,0)),"")) -> نهم | L13: =IF(COUNTA(C13:I13)=0,"",IF(AND(LEN(C13)=10,D13<>"",E13<>"",F13<>"",G13<>"",H13<>"",I13<>""),"کامل","ناقص")) -> کامل
A14: 10 | B14: 10 | C14: 0970739664 | D14: 0970739664 | E14: ماهان | F14: حسن زاده | G14: پسر | H14: 1391/11/08 | I14: 901 | J14: فردوسی 1 | K14: =IF(I14="","",IFERROR(INDEX(کلاس‌بندی!$F$5:$F$34,MATCH(I14,کلاس‌بندی!$D$5:$D$34,0)),"")) -> نهم | L14: =IF(COUNTA(C14:I14)=0,"",IF(AND(LEN(C14)=10,D14<>"",E14<>"",F14<>"",G14<>"",H14<>"",I14<>""),"کامل","ناقص")) -> کامل
A15: 11 | B15: 11 | C15: 0980347335 | D15: 0980347335 | E15: علي | F15: حسين زاده | G15: پسر | H15: 1390/10/16 | I15: 901 | J15: فردوسی 1 | K15: =IF(I15="","",IFERROR(INDEX(کلاس‌بندی!$F$5:$F$34,MATCH(I15,کلاس‌بندی!$D$5:$D$34,0)),"")) -> نهم | L15: =IF(COUNTA(C15:I15)=0,"",IF(AND(LEN(C15)=10,D15<>"",E15<>"",F15<>"",G15<>"",H15<>"",I15<>""),"کامل","ناقص")) -> کامل
A16: 12 | B16: 12 | C16: 0960322051 | D16: 0960322051 | E16: اميرحسين | F16: خواجوي | G16: پسر | H16: 1390/10/22 | I16: 901 | J16: فردوسی 1 | K16: =IF(I16="","",IFERROR(INDEX(کلاس‌بندی!$F$5:$F$34,MATCH(I16,کلاس‌بندی!$D$5:$D$34,0)),"")) -> نهم | L16: =IF(COUNTA(C16:I16)=0,"",IF(AND(LEN(C16)=10,D16<>"",E16<>"",F16<>"",G16<>"",H16<>"",I16<>""),"کامل","ناقص")) -> کامل
... A34: 30 | B34: 30 | C34: 0970583893 | D34: 0970583893 | E34: محمديوسف | F34: مظهري | G34: پسر | H34: 1391/04/15 | I34: 901 | J34: فردوسی 1 | K34: =IF(I34="","",IFERROR(INDEX(کلاس‌بندی!$F$5:$F$34,MATCH(I34,کلاس‌بندی!$D$5:$D$34,0)),"")) -> نهم | L34: =IF(COUNTA(C34:I34)=0,"",IF(AND(LEN(C34)=10,D34<>"",E34<>"",F34<>"",G34<>"",H34<>"",I34<>""),"کامل","ناقص")) -> کامل
A35: 31 | B35: 31 | C35: 2285780362 | D35: 2285780362 | E35: پارسامهر | F35: وزيري | G35: پسر | H35: 1390/07/17 | I35: 901 | J35: فردوسی 1 | K35: =IF(I35="","",IFERROR(INDEX(کلاس‌بندی!$F$5:$F$34,MATCH(I35,کلاس‌بندی!$D$5:$D$34,0)),"")) -> نهم | L35: =IF(COUNTA(C35:I35)=0,"",IF(AND(LEN(C35)=10,D35<>"",E35<>"",F35<>"",G35<>"",H35<>"",I35<>""),"کامل","ناقص")) -> کامل
A36: 32 | B36: 32 | C36: 0970624794 | D36: 0970624794 | E36: سجاد | F36: يعقوبي | G36: پسر | H36: 1391/06/08 | I36: 901 | J36: فردوسی 1 | K36: =IF(I36="","",IFERROR(INDEX(کلاس‌بندی!$F$5:$F$34,MATCH(I36,کلاس‌بندی!$D$5:$D$34,0)),"")) -> نهم | L36: =IF(COUNTA(C36:I36)=0,"",IF(AND(LEN(C36)=10,D36<>"",E36<>"",F36<>"",G36<>"",H36<>"",I36<>""),"کامل","ناقص")) -> کامل
A37: 33 | B37: 33 | J37: =IF(I37="","",IFERROR(INDEX(کلاس‌بندی!$E$5:$E$34,MATCH(I37,کلاس‌بندی!$D$5:$D$34,0)),"کد کلاس نامعتبر")) | K37: =IF(I37="","",IFERROR(INDEX(کلاس‌بندی!$F$5:$F$34,MATCH(I37,کلاس‌بندی!$D$5:$D$34,0)),"")) | L37: =IF(COUNTA(C37:I37)=0,"",IF(AND(LEN(C37)=10,D37<>"",E37<>"",F37<>"",G37<>"",H37<>"",I37<>""),"کامل","ناقص"))
A38: 34 | B38: 34 | J38: =IF(I38="","",IFERROR(INDEX(کلاس‌بندی!$E$5:$E$34,MATCH(I38,کلاس‌بندی!$D$5:$D$34,0)),"کد کلاس نامعتبر")) | K38: =IF(I38="","",IFERROR(INDEX(کلاس‌بندی!$F$5:$F$34,MATCH(I38,کلاس‌بندی!$D$5:$D$34,0)),"")) | L38: =IF(COUNTA(C38:I38)=0,"",IF(AND(LEN(C38)=10,D38<>"",E38<>"",F38<>"",G38<>"",H38<>"",I38<>""),"کامل","ناقص"))
A39: 35 | B39: 35 | J39: =IF(I39="","",IFERROR(INDEX(کلاس‌بندی!$E$5:$E$34,MATCH(I39,کلاس‌بندی!$D$5:$D$34,0)),"کد کلاس نامعتبر")) | K39: =IF(I39="","",IFERROR(INDEX(کلاس‌بندی!$F$5:$F$34,MATCH(I39,کلاس‌بندی!$D$5:$D$34,0)),"")) | L39: =IF(COUNTA(C39:I39)=0,"",IF(AND(LEN(C39)=10,D39<>"",E39<>"",F39<>"",G39<>"",H39<>"",I39<>""),"کامل","ناقص"))
A40: 36 | B40: 36 | J40: =IF(I40="","",IFERROR(INDEX(کلاس‌بندی!$E$5:$E$34,MATCH(I40,کلاس‌بندی!$D$5:$D$34,0)),"کد کلاس نامعتبر")) | K40: =IF(I40="","",IFERROR(INDEX(کلاس‌بندی!$F$5:$F$34,MATCH(I40,کلاس‌بندی!$D$5:$D$34,0)),"")) | L40: =IF(COUNTA(C40:I40)=0,"",IF(AND(LEN(C40)=10,D40<>"",E40<>"",F40<>"",G40<>"",H40<>"",I40<>""),"کامل","ناقص"))
A41: 37 | B41: 37 | J41: =IF(I41="","",IFERROR(INDEX(کلاس‌بندی!$E$5:$E$34,MATCH(I41,کلاس‌بندی!$D$5:$D$34,0)),"کد کلاس نامعتبر")) | K41: =IF(I41="","",IFERROR(INDEX(کلاس‌بندی!$F$5:$F$34,MATCH(I41,کلاس‌بندی!$D$5:$D$34,0)),"")) | L41: =IF(COUNTA(C41:I41)=0,"",IF(AND(LEN(C41)=10,D41<>"",E41<>"",F41<>"",G41<>"",H41<>"",I41<>""),"کامل","ناقص"))
A42: 38 | B42: 38 | J42: =IF(I42="","",IFERROR(INDEX(کلاس‌بندی!$E$5:$E$34,MATCH(I42,کلاس‌بندی!$D$5:$D$34,0)),"کد کلاس نامعتبر")) | K42: =IF(I42="","",IFERROR(INDEX(کلاس‌بندی!$F$5:$F$34,MATCH(I42,کلاس‌بندی!$D$5:$D$34,0)),"")) | L42: =IF(COUNTA(C42:I42)=0,"",IF(AND(LEN(C42)=10,D42<>"",E42<>"",F42<>"",G42<>"",H42<>"",I42<>""),"کامل","ناقص"))
A43: 39 | B43: 39 | J43: =IF(I43="","",IFERROR(INDEX(کلاس‌بندی!$E$5:$E$34,MATCH(I43,کلاس‌بندی!$D$5:$D$34,0)),"کد کلاس نامعتبر")) | K43: =IF(I43="","",IFERROR(INDEX(کلاس‌بندی!$F$5:$F$34,MATCH(I43,کلاس‌بندی!$D$5:$D$34,0)),"")) | L43: =IF(COUNTA(C43:I43)=0,"",IF(AND(LEN(C43)=10,D43<>"",E43<>"",F43<>"",G43<>"",H43<>"",I43<>""),"کامل","ناقص"))
A44: 40 | B44: 40 | J44: =IF(I44="","",IFERROR(INDEX(کلاس‌بندی!$E$5:$E$34,MATCH(I44,کلاس‌بندی!$D$5:$D$34,0)),"کد کلاس نامعتبر")) | K44: =IF(I44="","",IFERROR(INDEX(کلاس‌بندی!$F$5:$F$34,MATCH(I44,کلاس‌بندی!$D$5:$D$34,0)),"")) | L44: =IF(COUNTA(C44:I44)=0,"",IF(AND(LEN(C44)=10,D44<>"",E44<>"",F44<>"",G44<>"",H44<>"",I44<>""),"کامل","ناقص"))
A45: 41 | B45: 41 | J45: =IF(I45="","",IFERROR(INDEX(کلاس‌بندی!$E$5:$E$34,MATCH(I45,کلاس‌بندی!$D$5:$D$34,0)),"کد کلاس نامعتبر")) | K45: =IF(I45="","",IFERROR(INDEX(کلاس‌بندی!$F$5:$F$34,MATCH(I45,کلاس‌بندی!$D$5:$D$34,0)),"")) | L45: =IF(COUNTA(C45:I45)=0,"",IF(AND(LEN(C45)=10,D45<>"",E45<>"",F45<>"",G45<>"",H45<>"",I45<>""),"کامل","ناقص"))
A46: 42 | B46: 42 | J46: =IF(I46="","",IFERROR(INDEX(کلاس‌بندی!$E$5:$E$34,MATCH(I46,کلاس‌بندی!$D$5:$D$34,0)),"کد کلاس نامعتبر")) | K46: =IF(I46="","",IFERROR(INDEX(کلاس‌بندی!$F$5:$F$34,MATCH(I46,کلاس‌بندی!$D$5:$D$34,0)),"")) | L46: =IF(COUNTA(C46:I46)=0,"",IF(AND(LEN(C46)=10,D46<>"",E46<>"",F46<>"",G46<>"",H46<>"",I46<>""),"کامل","ناقص"))
A47: 43 | B47: 43 | J47: =IF(I47="","",IFERROR(INDEX(کلاس‌بندی!$E$5:$E$34,MATCH(I47,کلاس‌بندی!$D$5:$D$34,0)),"کد کلاس نامعتبر")) | K47: =IF(I47="","",IFERROR(INDEX(کلاس‌بندی!$F$5:$F$34,MATCH(I47,کلاس‌بندی!$D$5:$D$34,0)),"")) | L47: =IF(COUNTA(C47:I47)=0,"",IF(AND(LEN(C47)=10,D47<>"",E47<>"",F47<>"",G47<>"",H47<>"",I47<>""),"کامل","ناقص"))
A48: 44 | B48: 44 | J48: =IF(I48="","",IFERROR(INDEX(کلاس‌بندی!$E$5:$E$34,MATCH(I48,کلاس‌بندی!$D$5:$D$34,0)),"کد کلاس نامعتبر")) | K48: =IF(I48="","",IFERROR(INDEX(کلاس‌بندی!$F$5:$F$34,MATCH(I48,کلاس‌بندی!$D$5:$D$34,0)),"")) | L48: =IF(COUNTA(C48:I48)=0,"",IF(AND(LEN(C48)=10,D48<>"",E48<>"",F48<>"",G48<>"",H48<>"",I48<>""),"کامل","ناقص"))
... A104: 100 | B104: 100 | J104: =IF(I104="","",IFERROR(INDEX(کلاس‌بندی!$E$5:$E$34,MATCH(I104,کلاس‌بندی!$D$5:$D$34,0)),"کد کلاس نامعتبر")) | K104: =IF(I104="","",IFERROR(INDEX(کلاس‌بندی!$F$5:$F$34,MATCH(I104,کلاس‌بندی!$D$5:$D$34,0)),"")) | L104: =IF(COUNTA(C104:I104)=0,"",IF(AND(LEN(C104)=10,D104<>"",E104<>"",F104<>"",G104<>"",H104<>"",I104<>""),"کامل","ناقص"))

Sheet تنظیمات وزن‌دهی
A1: تنظیمات وزن‌دهی حوزه‌ها
A2: اوزان فعلی مطابق فایل مدرسه و مجموع آن‌ها ۱۰۰ است. برای حفظ سازگاری سامانه، نام و کد حوزه‌ها را تغییر ندهید.
A4: کد حوزه | B4: نام حوزه | C4: وزن درصدی | D4: تعداد شاخص | E4: شروع ستون شاخص | F4: پایان ستون شاخص
A5: EDU | B5: آموزشی | C5: 20 | D5: 8 | E5: G | F5: N
A6: DEV | B6: پرورشی | C6: 15 | D6: 5 | E6: O | F6: S
A7: CHR | B7: تربیتی | C7: 15 | D7: 2 | E7: T | F7: U
A8: DIS | B8: انضباطی | C8: 15 | D8: 5 | E8: V | F8: Z
A9: CUL | B9: فرهنگی | C9: 7 | D9: 3 | E9: AA | F9: AC
A10: RES | B10: پژوهشی | C10: 8 | D10: 6 | E10: AD | F10: AI
A11: SPT | B11: ورزشی | C11: 7 | D11: 7 | E11: AJ | F11: AP
A12: ART | B12: هنری | C12: 6 | D12: 7 | E12: AQ | F12: AW
A13: PER | B13: مهارت‌های فردی | C13: 7 | D13: 3 | E13: AX | F13: AZ
A15: جمع وزن‌ها | C15: =SUM(C5:C13) -> 100

Sheet بانک راهکارها
A1: بانک راهکارهای پیشنهادی
A2: برای دانش‌آموزانی که ارزیابی نهایی دارند، پیشنهاد بر اساس ضعیف‌ترین حوزه انتخاب می‌شود.
A4: ردیف | B4: حوزه | C4: راهکار پیشنهادی | D4: کاربرد
A5: 1 | B5: آموزشی | C5: جلسه فردی، برنامه مطالعه هدفمند و پیگیری هفتگی تکالیف پیشنهاد می‌شود. | D5: پس از بررسی مربی و شرایط دانش‌آموز اجرا شود.
A6: 2 | B6: پرورشی | C6: تقویت مسئولیت‌پذیری با نقش‌های کوچک کلاسی و بازخورد مثبت پیشنهاد می‌شود. | D6: پس از بررسی مربی و شرایط دانش‌آموز اجرا شود.
A7: 3 | B7: تربیتی | C7: تمرین هدف‌گذاری، خودارزیابی و مدیریت هیجان با همراهی مربی پیشنهاد می‌شود. | D7: پس از بررسی مربی و شرایط دانش‌آموز اجرا شود.
A8: 4 | B8: انضباطی | C8: قواعد روشن، قرارداد رفتاری کوتاه‌مدت و ثبت منظم پیشرفت پیشنهاد می‌شود. | D8: پس از بررسی مربی و شرایط دانش‌آموز اجرا شود.
A9: 5 | B9: فرهنگی | C9: مشارکت در برنامه‌های فرهنگی، مطالعه هدایت‌شده و فعالیت گروهی پیشنهاد می‌شود. | D9: پس از بررسی مربی و شرایط دانش‌آموز اجرا شود.
A10: 6 | B10: پژوهشی | C10: یک پروژه کوچک پژوهشی با منابع مشخص و ارائه کوتاه پیشنهاد می‌شود. | D10: پس از بررسی مربی و شرایط دانش‌آموز اجرا شود.
A11: 7 | B11: ورزشی | C11: برنامه فعالیت بدنی منظم و مشارکت در ورزش گروهی پیشنهاد می‌شود. | D11: پس از بررسی مربی و شرایط دانش‌آموز اجرا شود.
A12: 8 | B12: هنری | C12: انتخاب یک فعالیت هنری متناسب با علاقه و ارائه دوره‌ای اثر پیشنهاد می‌شود. | D12: پس از بررسی مربی و شرایط دانش‌آموز اجرا شود.
A13: 9 | B13: مهارت‌های فردی | C13: تمرین برنامه‌ریزی هفتگی، ارتباط مؤثر و کار تیمی پیشنهاد می‌شود. | D13: پس از بررسی مربی و شرایط دانش‌آموز اجرا شود.

Sheet ثبت اطلاعات
A1: ثبت ارزیابی و نمرات ماهانه
A2: هر دانش‌آموز ۱۲ ردیف دارد. ستون‌های زردِ شاخص‌ها را از ۰ تا ۵ تکمیل کنید؛ نتیجه نهایی فقط پس از ثبت هر ۴۶ شاخص نمایش داده می‌شود.
A4: ردیف | B4: ماه | C4: کد محلی | D4: کد ملی | E4: نام و نام خانوادگی | F4: کد کلاس | G4: EDU_01 | نمرات درسی | H4: EDU_02 | پیشرفت نسبت به قبل | I4: EDU_03 | انجام تکالیف | J4: EDU_04 | مشارکت در کلاس | K4: EDU_05 | دقت و تمرکز | L4: EDU_06 | مهارت حل مسئله | M4: EDU_07 | آمادگی برای امتحان | N4: EDU_08 | مطالعه غیر درسی | O4: DEV_01 | احترام به معلم و همکلاسی | P4: DEV_02 | مسئولیت‌پذیری | Q4: DEV_03 | همکاری با دیگران | R4: DEV_04 | ادب و رفتار اجتماعی | S4: DEV_05 | اعتماد به نفس | T4: CHR_01 | هدف‌گذاری | U4: CHR_02 | دوست یابی | V4: DIS_01 | حضور و غیاب | W4: DIS_02 | تأخیر | X4: DIS_03 | رعایت قوانین مدرسه | Y4: DIS_04 | رعایت پوشش | Z4: DIS_05 | احترام به مقررات کلاس | AA4: CUL_01 | مشارکت در برنامه‌های فرهنگی | AB4: CUL_02 | شناخت ارزش‌های اجتماعی | AC4: CUL_03 | رفتار مناسب در مراسم‌ها | AD4: RES_01 | انجام تحقیق | AE4: RES_02 | خلاقیت در پروژه‌ها | AF4: RES_03 | تحلیل اطلاعات | AG4: RES_04 | استفاده از منابع | AH4: RES_05 | نوآوری | AI4: RES_06 | پرسشگری | AJ4: SPT_01 | آمادگی جسمانی | AK4: SPT_02 | مشارکت در فعالیت‌های ورزشی | AL4: SPT_03 | روحیه تیمی | AM4: SPT_04 | رعایت قوانین بازی | AN4: SPT_05 | تلاش و پشتکار | AO4: SPT_06 | پیشرفت بدنی | AP4: SPT_07 | مهارت‌های حرکتی | AQ4: ART_01 | خلاقیت | AR4: ART_02 | مشارکت در فعالیت‌های هنری | AS4: ART_03 | مهارت در نقاشی / موسیقی / ... | AT4: ART_04 | دقت در کار هنری | AU4: ART_05 | نوآوری | AV4: ART_06 | علاقه‌مندی | AW4: ART_07 | ارائه آثار | AX4: PER_01 | مهارت ارتباطی | AY4: PER_02 | مهارت برنامه‌ریزی | AZ4: PER_03 | ارائه مطلب | CC4: امتیاز آموزشی (۰ تا ۲۰) | CD4: امتیاز پرورشی (۰ تا ۲۰) | CE4: امتیاز تربیتی (۰ تا ۲۰) | CF4: امتیاز انضباطی (۰ تا ۲۰) | CG4: امتیاز فرهنگی (۰ تا ۲۰) | CH4: امتیاز پژوهشی (۰ تا ۲۰) | CI4: امتیاز ورزشی (۰ تا ۲۰) | CJ4: امتیاز هنری (۰ تا ۲۰) | CK4: امتیاز مهارت‌های فردی (۰ تا ۲۰) | CL4: میانگین وزنی نهایی | CM4: سطح عملکرد | CN4: شماره ماه | CO4: درصد تکمیل | CP4: توضیحات
A5: 1 | B5: تیر | C5: =IF(دانش‌آموزان!E5="","",دانش‌آموزان!B5) -> 1 | D5: =IF(دانش‌آموزان!C5="","",دانش‌آموزان!C5) -> 0960326367 | E5: =IF(دانش‌آموزان!E5="","",دانش‌آموزان!E5&" "&دانش‌آموزان!F5) -> نيما اسكندري تربقان | F5: =IF(دانش‌آموزان!I5="","",دانش‌آموزان!I5) -> 901 | CC5: =IF(COUNT(G5:N5)=0,"",AVERAGE(G5:N5)*4) | CD5: =IF(COUNT(O5:S5)=0,"",AVERAGE(O5:S5)*4) | CE5: =IF(COUNT(T5:U5)=0,"",AVERAGE(T5:U5)*4) | CF5: =IF(COUNT(V5:Z5)=0,"",AVERAGE(V5:Z5)*4) | CG5: =IF(COUNT(AA5:AC5)=0,"",AVERAGE(AA5:AC5)*4) | CH5: =IF(COUNT(AD5:AI5)=0,"",AVERAGE(AD5:AI5)*4) | CI5: =IF(COUNT(AJ5:AP5)=0,"",AVERAGE(AJ5:AP5)*4) | CJ5: =IF(COUNT(AQ5:AW5)=0,"",AVERAGE(AQ5:AW5)*4) | CK5: =IF(COUNT(AX5:AZ5)=0,"",AVERAGE(AX5:AZ5)*4) | CL5: =IF(C5="","",IF(COUNT(G5:AZ5)<46,"",SUMPRODUCT(CC5:CK5,'تنظیمات وزن‌دهی'!$C$5:$C$13)/100)) | CM5: =IF(C5="","",IF(COUNT(G5:AZ5)=0,"",IF(COUNT(G5:AZ5)<46,"موقت - اطلاعات ناقص",IF(CL5>=17,"عالی",IF(CL5>=14,"خوب",IF(CL5>=10,"متوسط","ضعیف")))))) | CN5: 1 | CO5: =IF(C5="","",COUNT(G5:AZ5)/46) -> 0
A6: 2 | B6: مرداد | C6: =IF(دانش‌آموزان!E5="","",دانش‌آموزان!B5) -> 1 | D6: =IF(دانش‌آموزان!C5="","",دانش‌آموزان!C5) -> 0960326367 | E6: =IF(دانش‌آموزان!E5="","",دانش‌آموزان!E5&" "&دانش‌آموزان!F5) -> نيما اسكندري تربقان | F6: =IF(دانش‌آموزان!I5="","",دانش‌آموزان!I5) -> 901 | CC6: =IF(COUNT(G6:N6)=0,"",AVERAGE(G6:N6)*4) | CD6: =IF(COUNT(O6:S6)=0,"",AVERAGE(O6:S6)*4) | CE6: =IF(COUNT(T6:U6)=0,"",AVERAGE(T6:U6)*4) | CF6: =IF(COUNT(V6:Z6)=0,"",AVERAGE(V6:Z6)*4) | CG6: =IF(COUNT(AA6:AC6)=0,"",AVERAGE(AA6:AC6)*4) | CH6: =IF(COUNT(AD6:AI6)=0,"",AVERAGE(AD6:AI6)*4) | CI6: =IF(COUNT(AJ6:AP6)=0,"",AVERAGE(AJ6:AP6)*4) | CJ6: =IF(COUNT(AQ6:AW6)=0,"",AVERAGE(AQ6:AW6)*4) | CK6: =IF(COUNT(AX6:AZ6)=0,"",AVERAGE(AX6:AZ6)*4) | CL6: =IF(C6="","",IF(COUNT(G6:AZ6)<46,"",SUMPRODUCT(CC6:CK6,'تنظیمات وزن‌دهی'!$C$5:$C$13)/100)) | CM6: =IF(C6="","",IF(COUNT(G6:AZ6)=0,"",IF(COUNT(G6:AZ6)<46,"موقت - اطلاعات ناقص",IF(CL6>=17,"عالی",IF(CL6>=14,"خوب",IF(CL6>=10,"متوسط","ضعیف")))))) | CN6: 2 | CO6: =IF(C6="","",COUNT(G6:AZ6)/46) -> 0
A7: 3 | B7: شهریور | C7: =IF(دانش‌آموزان!E5="","",دانش‌آموزان!B5) -> 1 | D7: =IF(دانش‌آموزان!C5="","",دانش‌آموزان!C5) -> 0960326367 | E7: =IF(دانش‌آموزان!E5="","",دانش‌آموزان!E5&" "&دانش‌آموزان!F5) -> نيما اسكندري تربقان | F7: =IF(دانش‌آموزان!I5="","",دانش‌آموزان!I5) -> 901 | G7: 19 | H7: 0 | I7: 0 | J7: 0 | K7: 0 | L7: 0 | M7: 0 | N7: 0 | O7: 0 | P7: 0 | Q7: 0 | R7: 0 | S7: 0 | T7: 0 | U7: 0 | V7: 1 | W7: 0 | X7: 3 | Y7: 0 | Z7: 0 | AA7: 0 | AB7: 0 | AC7: 0 | AD7: 0 | AE7: 0 | AF7: 0 | AG7: 0 | AH7: 0 | AI7: 0 | AJ7: 0 | AK7: 0 | AL7: 0 | AM7: 0 | AN7: 0 | AO7: 0 | AP7: 0 | AQ7: 0 | AR7: 0 | AS7: 0 | AT7: 0 | AU7: 0 | AV7: 0 | AW7: 0 | AX7: 0 | AY7: 0 | AZ7: 0 | CC7: =IF(COUNT(G7:N7)=0,"",AVERAGE(G7:N7)*4) -> 9.5 | CD7: =IF(COUNT(O7:S7)=0,"",AVERAGE(O7:S7)*4) -> 0 | CE7: =IF(COUNT(T7:U7)=0,"",AVERAGE(T7:U7)*4) -> 0 | CF7: =IF(COUNT(V7:Z7)=0,"",AVERAGE(V7:Z7)*4) -> 3.2 | CG7: =IF(COUNT(AA7:AC7)=0,"",AVERAGE(AA7:AC7)*4) -> 0 | CH7: =IF(COUNT(AD7:AI7)=0,"",AVERAGE(AD7:AI7)*4) -> 0 | CI7: =IF(COUNT(AJ7:AP7)=0,"",AVERAGE(AJ7:AP7)*4) -> 0 | CJ7: =IF(COUNT(AQ7:AW7)=0,"",AVERAGE(AQ7:AW7)*4) -> 0 | CK7: =IF(COUNT(AX7:AZ7)=0,"",AVERAGE(AX7:AZ7)*4) -> 0 | CL7: =IF(C7="","",IF(COUNT(G7:AZ7)<46,"",SUMPRODUCT(CC7:CK7,'تنظیمات وزن‌دهی'!$C$5:$C$13)/100)) -> #VALUE! | CM7: =IF(C7="","",IF(COUNT(G7:AZ7)=0,"",IF(COUNT(G7:AZ7)<46,"موقت - اطلاعات ناقص",IF(CL7>=17,"عالی",IF(CL7>=14,"خوب",IF(CL7>=10,"متوسط","ضعیف")))))) -> #VALUE! | CN7: 3 | CO7: =IF(C7="","",COUNT(G7:AZ7)/46) -> 1
A8: 4 | B8: مهر | C8: =IF(دانش‌آموزان!E5="","",دانش‌آموزان!B5) -> 1 | D8: =IF(دانش‌آموزان!C5="","",دانش‌آموزان!C5) -> 0960326367 | E8: =IF(دانش‌آموزان!E5="","",دانش‌آموزان!E5&" "&دانش‌آموزان!F5) -> نيما اسكندري تربقان | F8: =IF(دانش‌آموزان!I5="","",دانش‌آموزان!I5) -> 901 | CC8: =IF(COUNT(G8:N8)=0,"",AVERAGE(G8:N8)*4) | CD8: =IF(COUNT(O8:S8)=0,"",AVERAGE(O8:S8)*4) | CE8: =IF(COUNT(T8:U8)=0,"",AVERAGE(T8:U8)*4) | CF8: =IF(COUNT(V8:Z8)=0,"",AVERAGE(V8:Z8)*4) | CG8: =IF(COUNT(AA8:AC8)=0,"",AVERAGE(AA8:AC8)*4) | CH8: =IF(COUNT(AD8:AI8)=0,"",AVERAGE(AD8:AI8)*4) | CI8: =IF(COUNT(AJ8:AP8)=0,"",AVERAGE(AJ8:AP8)*4) | CJ8: =IF(COUNT(AQ8:AW8)=0,"",AVERAGE(AQ8:AW8)*4) | CK8: =IF(COUNT(AX8:AZ8)=0,"",AVERAGE(AX8:AZ8)*4) | CL8: =IF(C8="","",IF(COUNT(G8:AZ8)<46,"",SUMPRODUCT(CC8:CK8,'تنظیمات وزن‌دهی'!$C$5:$C$13)/100)) | CM8: =IF(C8="","",IF(COUNT(G8:AZ8)=0,"",IF(COUNT(G8:AZ8)<46,"موقت - اطلاعات ناقص",IF(CL8>=17,"عالی",IF(CL8>=14,"خوب",IF(CL8>=10,"متوسط","ضعیف")))))) | CN8: 4 | CO8: =IF(C8="","",COUNT(G8:AZ8)/46) -> 0
A9: 5 | B9: آبان | C9: =IF(دانش‌آموزان!E5="","",دانش‌آموزان!B5) -> 1 | D9: =IF(دانش‌آموزان!C5="","",دانش‌آموزان!C5) -> 0960326367 | E9: =IF(دانش‌آموزان!E5="","",دانش‌آموزان!E5&" "&دانش‌آموزان!F5) -> نيما اسكندري تربقان | F9: =IF(دانش‌آموزان!I5="","",دانش‌آموزان!I5) -> 901 | CC9: =IF(COUNT(G9:N9)=0,"",AVERAGE(G9:N9)*4) | CD9: =IF(COUNT(O9:S9)=0,"",AVERAGE(O9:S9)*4) | CE9: =IF(COUNT(T9:U9)=0,"",AVERAGE(T9:U9)*4) | CF9: =IF(COUNT(V9:Z9)=0,"",AVERAGE(V9:Z9)*4) | CG9: =IF(COUNT(AA9:AC9)=0,"",AVERAGE(AA9:AC9)*4) | CH9: =IF(COUNT(AD9:AI9)=0,"",AVERAGE(AD9:AI9)*4) | CI9: =IF(COUNT(AJ9:AP9)=0,"",AVERAGE(AJ9:AP9)*4) | CJ9: =IF(COUNT(AQ9:AW9)=0,"",AVERAGE(AQ9:AW9)*4) | CK9: =IF(COUNT(AX9:AZ9)=0,"",AVERAGE(AX9:AZ9)*4) | CL9: =IF(C9="","",IF(COUNT(G9:AZ9)<46,"",SUMPRODUCT(CC9:CK9,'تنظیمات وزن‌دهی'!$C$5:$C$13)/100)) | CM9: =IF(C9="","",IF(COUNT(G9:AZ9)=0,"",IF(COUNT(G9:AZ9)<46,"موقت - اطلاعات ناقص",IF(CL9>=17,"عالی",IF(CL9>=14,"خوب",IF(CL9>=10,"متوسط","ضعیف")))))) | CN9: 5 | CO9: =IF(C9="","",COUNT(G9:AZ9)/46) -> 0
A10: 6 | B10: آذر | C10: =IF(دانش‌آموزان!E5="","",دانش‌آموزان!B5) -> 1 | D10: =IF(دانش‌آموزان!C5="","",دانش‌آموزان!C5) -> 0960326367 | E10: =IF(دانش‌آموزان!E5="","",دانش‌آموزان!E5&" "&دانش‌آموزان!F5) -> نيما اسكندري تربقان | F10: =IF(دانش‌آموزان!I5="","",دانش‌آموزان!I5) -> 901 | CC10: =IF(COUNT(G10:N10)=0,"",AVERAGE(G10:N10)*4) | CD10: =IF(COUNT(O10:S10)=0,"",AVERAGE(O10:S10)*4) | CE10: =IF(COUNT(T10:U10)=0,"",AVERAGE(T10:U10)*4) | CF10: =IF(COUNT(V10:Z10)=0,"",AVERAGE(V10:Z10)*4) | CG10: =IF(COUNT(AA10:AC10)=0,"",AVERAGE(AA10:AC10)*4) | CH10: =IF(COUNT(AD10:AI10)=0,"",AVERAGE(AD10:AI10)*4) | CI10: =IF(COUNT(AJ10:AP10)=0,"",AVERAGE(AJ10:AP10)*4) | CJ10: =IF(COUNT(AQ10:AW10)=0,"",AVERAGE(AQ10:AW10)*4) | CK10: =IF(COUNT(AX10:AZ10)=0,"",AVERAGE(AX10:AZ10)*4) | CL10: =IF(C10="","",IF(COUNT(G10:AZ10)<46,"",SUMPRODUCT(CC10:CK10,'تنظیمات وزن‌دهی'!$C$5:$C$13)/100)) | CM10: =IF(C10="","",IF(COUNT(G10:AZ10)=0,"",IF(COUNT(G10:AZ10)<46,"موقت - اطلاعات ناقص",IF(CL10>=17,"عالی",IF(CL10>=14,"خوب",IF(CL10>=10,"متوسط","ضعیف")))))) | CN10: 6 | CO10: =IF(C10="","",COUNT(G10:AZ10)/46) -> 0
A11: 7 | B11: دی | C11: =IF(دانش‌آموزان!E5="","",دانش‌آموزان!B5) -> 1 | D11: =IF(دانش‌آموزان!C5="","",دانش‌آموزان!C5) -> 0960326367 | E11: =IF(دانش‌آموزان!E5="","",دانش‌آموزان!E5&" "&دانش‌آموزان!F5) -> نيما اسكندري تربقان | F11: =IF(دانش‌آموزان!I5="","",دانش‌آموزان!I5) -> 901 | CC11: =IF(COUNT(G11:N11)=0,"",AVERAGE(G11:N11)*4) | CD11: =IF(COUNT(O11:S11)=0,"",AVERAGE(O11:S11)*4) | CE11: =IF(COUNT(T11:U11)=0,"",AVERAGE(T11:U11)*4) | CF11: =IF(COUNT(V11:Z11)=0,"",AVERAGE(V11:Z11)*4) | CG11: =IF(COUNT(AA11:AC11)=0,"",AVERAGE(AA11:AC11)*4) | CH11: =IF(COUNT(AD11:AI11)=0,"",AVERAGE(AD11:AI11)*4) | CI11: =IF(COUNT(AJ11:AP11)=0,"",AVERAGE(AJ11:AP11)*4) | CJ11: =IF(COUNT(AQ11:AW11)=0,"",AVERAGE(AQ11:AW11)*4) | CK11: =IF(COUNT(AX11:AZ11)=0,"",AVERAGE(AX11:AZ11)*4) | CL11: =IF(C11="","",IF(COUNT(G11:AZ11)<46,"",SUMPRODUCT(CC11:CK11,'تنظیمات وزن‌دهی'!$C$5:$C$13)/100)) | CM11: =IF(C11="","",IF(COUNT(G11:AZ11)=0,"",IF(COUNT(G11:AZ11)<46,"موقت - اطلاعات ناقص",IF(CL11>=17,"عالی",IF(CL11>=14,"خوب",IF(CL11>=10,"متوسط","ضعیف")))))) | CN11: 7 | CO11: =IF(C11="","",COUNT(G11:AZ11)/46) -> 0
A12: 8 | B12: بهمن | C12: =IF(دانش‌آموزان!E5="","",دانش‌آموزان!B5) -> 1 | D12: =IF(دانش‌آموزان!C5="","",دانش‌آموزان!C5) -> 0960326367 | E12: =IF(دانش‌آموزان!E5="","",دانش‌آموزان!E5&" "&دانش‌آموزان!F5) -> نيما اسكندري تربقان | F12: =IF(دانش‌آموزان!I5="","",دانش‌آموزان!I5) -> 901 | CC12: =IF(COUNT(G12:N12)=0,"",AVERAGE(G12:N12)*4) | CD12: =IF(COUNT(O12:S12)=0,"",AVERAGE(O12:S12)*4) | CE12: =IF(COUNT(T12:U12)=0,"",AVERAGE(T12:U12)*4) | CF12: =IF(COUNT(V12:Z12)=0,"",AVERAGE(V12:Z12)*4) | CG12: =IF(COUNT(AA12:AC12)=0,"",AVERAGE(AA12:AC12)*4) | CH12: =IF(COUNT(AD12:AI12)=0,"",AVERAGE(AD12:AI12)*4) | CI12: =IF(COUNT(AJ12:AP12)=0,"",AVERAGE(AJ12:AP12)*4) | CJ12: =IF(COUNT(AQ12:AW12)=0,"",AVERAGE(AQ12:AW12)*4) | CK12: =IF(COUNT(AX12:AZ12)=0,"",AVERAGE(AX12:AZ12)*4) | CL12: =IF(C12="","",IF(COUNT(G12:AZ12)<46,"",SUMPRODUCT(CC12:CK12,'تنظیمات وزن‌دهی'!$C$5:$C$13)/100)) | CM12: =IF(C12="","",IF(COUNT(G12:AZ12)=0,"",IF(COUNT(G12:AZ12)<46,"موقت - اطلاعات ناقص",IF(CL12>=17,"عالی",IF(CL12>=14,"خوب",IF(CL12>=10,"متوسط","ضعیف")))))) | CN12: 8 | CO12: =IF(C12="","",COUNT(G12:AZ12)/46) -> 0
A13: 9 | B13: اسفند | C13: =IF(دانش‌آموزان!E5="","",دانش‌آموزان!B5) -> 1 | D13: =IF(دانش‌آموزان!C5="","",دانش‌آموزان!C5) -> 0960326367 | E13: =IF(دانش‌آموزان!E5="","",دانش‌آموزان!E5&" "&دانش‌آموزان!F5) -> نيما اسكندري تربقان | F13: =IF(دانش‌آموزان!I5="","",دانش‌آموزان!I5) -> 901 | CC13: =IF(COUNT(G13:N13)=0,"",AVERAGE(G13:N13)*4) | CD13: =IF(COUNT(O13:S13)=0,"",AVERAGE(O13:S13)*4) | CE13: =IF(COUNT(T13:U13)=0,"",AVERAGE(T13:U13)*4) | CF13: =IF(COUNT(V13:Z13)=0,"",AVERAGE(V13:Z13)*4) | CG13: =IF(COUNT(AA13:AC13)=0,"",AVERAGE(AA13:AC13)*4) | CH13: =IF(COUNT(AD13:AI13)=0,"",AVERAGE(AD13:AI13)*4) | CI13: =IF(COUNT(AJ13:AP13)=0,"",AVERAGE(AJ13:AP13)*4) | CJ13: =IF(COUNT(AQ13:AW13)=0,"",AVERAGE(AQ13:AW13)*4) | CK13: =IF(COUNT(AX13:AZ13)=0,"",AVERAGE(AX13:AZ13)*4) | CL13: =IF(C13="","",IF(COUNT(G13:AZ13)<46,"",SUMPRODUCT(CC13:CK13,'تنظیمات وزن‌دهی'!$C$5:$C$13)/100)) | CM13: =IF(C13="","",IF(COUNT(G13:AZ13)=0,"",IF(COUNT(G13:AZ13)<46,"موقت - اطلاعات ناقص",IF(CL13>=17,"عالی",IF(CL13>=14,"خوب",IF(CL13>=10,"متوسط","ضعیف")))))) | CN13: 9 | CO13: =IF(C13="","",COUNT(G13:AZ13)/46) -> 0
A14: 10 | B14: فروردین | C14: =IF(دانش‌آموزان!E5="","",دانش‌آموزان!B5) -> 1 | D14: =IF(دانش‌آموزان!C5="","",دانش‌آموزان!C5) -> 0960326367 | E14: =IF(دانش‌آموزان!E5="","",دانش‌آموزان!E5&" "&دانش‌آموزان!F5) -> نيما اسكندري تربقان | F14: =IF(دانش‌آموزان!I5="","",دانش‌آموزان!I5) -> 901 | CC14: =IF(COUNT(G14:N14)=0,"",AVERAGE(G14:N14)*4) | CD14: =IF(COUNT(O14:S14)=0,"",AVERAGE(O14:S14)*4) | CE14: =IF(COUNT(T14:U14)=0,"",AVERAGE(T14:U14)*4) | CF14: =IF(COUNT(V14:Z14)=0,"",AVERAGE(V14:Z14)*4) | CG14: =IF(COUNT(AA14:AC14)=0,"",AVERAGE(AA14:AC14)*4) | CH14: =IF(COUNT(AD14:AI14)=0,"",AVERAGE(AD14:AI14)*4) | CI14: =IF(COUNT(AJ14:AP14)=0,"",AVERAGE(AJ14:AP14)*4) | CJ14: =IF(COUNT(AQ14:AW14)=0,"",AVERAGE(AQ14:AW14)*4) | CK14: =IF(COUNT(AX14:AZ14)=0,"",AVERAGE(AX14:AZ14)*4) | CL14: =IF(C14="","",IF(COUNT(G14:AZ14)<46,"",SUMPRODUCT(CC14:CK14,'تنظیمات وزن‌دهی'!$C$5:$C$13)/100)) | CM14: =IF(C14="","",IF(COUNT(G14:AZ14)=0,"",IF(COUNT(G14:AZ14)<46,"موقت - اطلاعات ناقص",IF(CL14>=17,"عالی",IF(CL14>=14,"خوب",IF(CL14>=10,"متوسط","ضعیف")))))) | CN14: 10 | CO14: =IF(C14="","",COUNT(G14:AZ14)/46) -> 0
A15: 11 | B15: اردیبهشت | C15: =IF(دانش‌آموزان!E5="","",دانش‌آموزان!B5) -> 1 | D15: =IF(دانش‌آموزان!C5="","",دانش‌آموزان!C5) -> 0960326367 | E15: =IF(دانش‌آموزان!E5="","",دانش‌آموزان!E5&" "&دانش‌آموزان!F5) -> نيما اسكندري تربقان | F15: =IF(دانش‌آموزان!I5="","",دانش‌آموزان!I5) -> 901 | CC15: =IF(COUNT(G15:N15)=0,"",AVERAGE(G15:N15)*4) | CD15: =IF(COUNT(O15:S15)=0,"",AVERAGE(O15:S15)*4) | CE15: =IF(COUNT(T15:U15)=0,"",AVERAGE(T15:U15)*4) | CF15: =IF(COUNT(V15:Z15)=0,"",AVERAGE(V15:Z15)*4) | CG15: =IF(COUNT(AA15:AC15)=0,"",AVERAGE(AA15:AC15)*4) | CH15: =IF(COUNT(AD15:AI15)=0,"",AVERAGE(AD15:AI15)*4) | CI15: =IF(COUNT(AJ15:AP15)=0,"",AVERAGE(AJ15:AP15)*4) | CJ15: =IF(COUNT(AQ15:AW15)=0,"",AVERAGE(AQ15:AW15)*4) | CK15: =IF(COUNT(AX15:AZ15)=0,"",AVERAGE(AX15:AZ15)*4) | CL15: =IF(C15="","",IF(COUNT(G15:AZ15)<46,"",SUMPRODUCT(CC15:CK15,'تنظیمات وزن‌دهی'!$C$5:$C$13)/100)) | CM15: =IF(C15="","",IF(COUNT(G15:AZ15)=0,"",IF(COUNT(G15:AZ15)<46,"موقت - اطلاعات ناقص",IF(CL15>=17,"عالی",IF(CL15>=14,"خوب",IF(CL15>=10,"متوسط","ضعیف")))))) | CN15: 11 | CO15: =IF(C15="","",COUNT(G15:AZ15)/46) -> 0
A16: 12 | B16: خرداد | C16: =IF(دانش‌آموزان!E5="","",دانش‌آموزان!B5) -> 1 | D16: =IF(دانش‌آموزان!C5="","",دانش‌آموزان!C5) -> 0960326367 | E16: =IF(دانش‌آموزان!E5="","",دانش‌آموزان!E5&" "&دانش‌آموزان!F5) -> نيما اسكندري تربقان | F16: =IF(دانش‌آموزان!I5="","",دانش‌آموزان!I5) -> 901 | CC16: =IF(COUNT(G16:N16)=0,"",AVERAGE(G16:N16)*4) | CD16: =IF(COUNT(O16:S16)=0,"",AVERAGE(O16:S16)*4) | CE16: =IF(COUNT(T16:U16)=0,"",AVERAGE(T16:U16)*4) | CF16: =IF(COUNT(V16:Z16)=0,"",AVERAGE(V16:Z16)*4) | CG16: =IF(COUNT(AA16:AC16)=0,"",AVERAGE(AA16:AC16)*4) | CH16: =IF(COUNT(AD16:AI16)=0,"",AVERAGE(AD16:AI16)*4) | CI16: =IF(COUNT(AJ16:AP16)=0,"",AVERAGE(AJ16:AP16)*4) | CJ16: =IF(COUNT(AQ16:AW16)=0,"",AVERAGE(AQ16:AW16)*4) | CK16: =IF(COUNT(AX16:AZ16)=0,"",AVERAGE(AX16:AZ16)*4) | CL16: =IF(C16="","",IF(COUNT(G16:AZ16)<46,"",SUMPRODUCT(CC16:CK16,'تنظیمات وزن‌دهی'!$C$5:$C$13)/100)) | CM16: =IF(C16="","",IF(COUNT(G16:AZ16)=0,"",IF(COUNT(G16:AZ16)<46,"موقت - اطلاعات ناقص",IF(CL16>=17,"عالی",IF(CL16>=14,"خوب",IF(CL16>=10,"متوسط","ضعیف")))))) | CN16: 12 | CO16: =IF(C16="","",COUNT(G16:AZ16)/46) -> 0
A17: 13 | B17: تیر | C17: =IF(دانش‌آموزان!E6="","",دانش‌آموزان!B6) -> 2 | D17: =IF(دانش‌آموزان!C6="","",دانش‌آموزان!C6) -> 0980506328 | E17: =IF(دانش‌آموزان!E6="","",دانش‌آموزان!E6&" "&دانش‌آموزان!F6) -> اميررضا اميري | F17: =IF(دانش‌آموزان!I6="","",دانش‌آموزان!I6) -> 901 | CC17: =IF(COUNT(G17:N17)=0,"",AVERAGE(G17:N17)*4) | CD17: =IF(COUNT(O17:S17)=0,"",AVERAGE(O17:S17)*4) | CE17: =IF(COUNT(T17:U17)=0,"",AVERAGE(T17:U17)*4) | CF17: =IF(COUNT(V17:Z17)=0,"",AVERAGE(V17:Z17)*4) | CG17: =IF(COUNT(AA17:AC17)=0,"",AVERAGE(AA17:AC17)*4) | CH17: =IF(COUNT(AD17:AI17)=0,"",AVERAGE(AD17:AI17)*4) | CI17: =IF(COUNT(AJ17:AP17)=0,"",AVERAGE(AJ17:AP17)*4) | CJ17: =IF(COUNT(AQ17:AW17)=0,"",AVERAGE(AQ17:AW17)*4) | CK17: =IF(COUNT(AX17:AZ17)=0,"",AVERAGE(AX17:AZ17)*4) | CL17: =IF(C17="","",IF(COUNT(G17:AZ17)<46,"",SUMPRODUCT(CC17:CK17,'تنظیمات وزن‌دهی'!$C$5:$C$13)/100)) | CM17: =IF(C17="","",IF(COUNT(G17:AZ17)=0,"",IF(COUNT(G17:AZ17)<46,"موقت - اطلاعات ناقص",IF(CL17>=17,"عالی",IF(CL17>=14,"خوب",IF(CL17>=10,"متوسط","ضعیف")))))) | CN17: 1 | CO17: =IF(C17="","",COUNT(G17:AZ17)/46) -> 0
A18: 14 | B18: مرداد | C18: =IF(دانش‌آموزان!E6="","",دانش‌آموزان!B6) -> 2 | D18: =IF(دانش‌آموزان!C6="","",دانش‌آموزان!C6) -> 0980506328 | E18: =IF(دانش‌آموزان!E6="","",دانش‌آموزان!E6&" "&دانش‌آموزان!F6) -> اميررضا اميري | F18: =IF(دانش‌آموزان!I6="","",دانش‌آموزان!I6) -> 901 | CC18: =IF(COUNT(G18:N18)=0,"",AVERAGE(G18:N18)*4) | CD18: =IF(COUNT(O18:S18)=0,"",AVERAGE(O18:S18)*4) | CE18: =IF(COUNT(T18:U18)=0,"",AVERAGE(T18:U18)*4) | CF18: =IF(COUNT(V18:Z18)=0,"",AVERAGE(V18:Z18)*4) | CG18: =IF(COUNT(AA18:AC18)=0,"",AVERAGE(AA18:AC18)*4) | CH18: =IF(COUNT(AD18:AI18)=0,"",AVERAGE(AD18:AI18)*4) | CI18: =IF(COUNT(AJ18:AP18)=0,"",AVERAGE(AJ18:AP18)*4) | CJ18: =IF(COUNT(AQ18:AW18)=0,"",AVERAGE(AQ18:AW18)*4) | CK18: =IF(COUNT(AX18:AZ18)=0,"",AVERAGE(AX18:AZ18)*4) | CL18: =IF(C18="","",IF(COUNT(G18:AZ18)<46,"",SUMPRODUCT(CC18:CK18,'تنظیمات وزن‌دهی'!$C$5:$C$13)/100)) | CM18: =IF(C18="","",IF(COUNT(G18:AZ18)=0,"",IF(COUNT(G18:AZ18)<46,"موقت - اطلاعات ناقص",IF(CL18>=17,"عالی",IF(CL18>=14,"خوب",IF(CL18>=10,"متوسط","ضعیف")))))) | CN18: 2 | CO18: =IF(C18="","",COUNT(G18:AZ18)/46) -> 0
A19: 15 | B19: شهریور | C19: =IF(دانش‌آموزان!E6="","",دانش‌آموزان!B6) -> 2 | D19: =IF(دانش‌آموزان!C6="","",دانش‌آموزان!C6) -> 0980506328 | E19: =IF(دانش‌آموزان!E6="","",دانش‌آموزان!E6&" "&دانش‌آموزان!F6) -> اميررضا اميري | F19: =IF(دانش‌آموزان!I6="","",دانش‌آموزان!I6) -> 901 | G19: 19.27 | H19: -4.27 | I19: 0 | J19: 0 | K19: 0 | L19: 0 | M19: 0 | N19: 0 | O19: 4 | P19: 4 | Q19: 4 | R19: 4 | S19: 0 | T19: 0 | U19: 4 | V19: 3 | W19: 4 | X19: 4 | Y19: 4 | Z19: 4 | AA19: 0 | AB19: 0 | AC19: 0 | AD19: 0 | AE19: 0 | AF19: 0 | AG19: 0 | AH19: 0 | AI19: 0 | AJ19: 0 | AK19: 0 | AL19: 0 | AM19: 0 | AN19: 0 | AO19: 0 | AP19: 0 | AQ19: 0 | AR19: 0 | AS19: 0 | AT19: 0 | AU19: 0 | AV19: 0 | AW19: 0 | AX19: 0 | AY19: 0 | AZ19: 0 | CC19: =IF(COUNT(G19:N19)=0,"",AVERAGE(G19:N19)*4) -> 7.5 | CD19: =IF(COUNT(O19:S19)=0,"",AVERAGE(O19:S19)*4) -> 12.8 | CE19: =IF(COUNT(T19:U19)=0,"",AVERAGE(T19:U19)*4) -> 8 | CF19: =IF(COUNT(V19:Z19)=0,"",AVERAGE(V19:Z19)*4) -> 15.2 | CG19: =IF(COUNT(AA19:AC19)=0,"",AVERAGE(AA19:AC19)*4) -> 0 | CH19: =IF(COUNT(AD19:AI19)=0,"",AVERAGE(AD19:AI19)*4) -> 0 | CI19: =IF(COUNT(AJ19:AP19)=0,"",AVERAGE(AJ19:AP19)*4) -> 0 | CJ19: =IF(COUNT(AQ19:AW19)=0,"",AVERAGE(AQ19:AW19)*4) -> 0 | CK19: =IF(COUNT(AX19:AZ19)=0,"",AVERAGE(AX19:AZ19)*4) -> 0 | CL19: =IF(C19="","",IF(COUNT(G19:AZ19)<46,"",SUMPRODUCT(CC19:CK19,'تنظیمات وزن‌دهی'!$C$5:$C$13)/100)) -> #VALUE! | CM19: =IF(C19="","",IF(COUNT(G19:AZ19)=0,"",IF(COUNT(G19:AZ19)<46,"موقت - اطلاعات ناقص",IF(CL19>=17,"عالی",IF(CL19>=14,"خوب",IF(CL19>=10,"متوسط","ضعیف")))))) -> #VALUE! | CN19: 3 | CO19: =IF(C19="","",COUNT(G19:AZ19)/46) -> 1
A20: 16 | B20: مهر | C20: =IF(دانش‌آموزان!E6="","",دانش‌آموزان!B6) -> 2 | D20: =IF(دانش‌آموزان!C6="","",دانش‌آموزان!C6) -> 0980506328 | E20: =IF(دانش‌آموزان!E6="","",دانش‌آموزان!E6&" "&دانش‌آموزان!F6) -> اميررضا اميري | F20: =IF(دانش‌آموزان!I6="","",دانش‌آموزان!I6) -> 901 | CC20: =IF(COUNT(G20:N20)=0,"",AVERAGE(G20:N20)*4) | CD20: =IF(COUNT(O20:S20)=0,"",AVERAGE(O20:S20)*4) | CE20: =IF(COUNT(T20:U20)=0,"",AVERAGE(T20:U20)*4) | CF20: =IF(COUNT(V20:Z20)=0,"",AVERAGE(V20:Z20)*4) | CG20: =IF(COUNT(AA20:AC20)=0,"",AVERAGE(AA20:AC20)*4) | CH20: =IF(COUNT(AD20:AI20)=0,"",AVERAGE(AD20:AI20)*4) | CI20: =IF(COUNT(AJ20:AP20)=0,"",AVERAGE(AJ20:AP20)*4) | CJ20: =IF(COUNT(AQ20:AW20)=0,"",AVERAGE(AQ20:AW20)*4) | CK20: =IF(COUNT(AX20:AZ20)=0,"",AVERAGE(AX20:AZ20)*4) | CL20: =IF(C20="","",IF(COUNT(G20:AZ20)<46,"",SUMPRODUCT(CC20:CK20,'تنظیمات وزن‌دهی'!$C$5:$C$13)/100)) | CM20: =IF(C20="","",IF(COUNT(G20:AZ20)=0,"",IF(COUNT(G20:AZ20)<46,"موقت - اطلاعات ناقص",IF(CL20>=17,"عالی",IF(CL20>=14,"خوب",IF(CL20>=10,"متوسط","ضعیف")))))) | CN20: 4 | CO20: =IF(C20="","",COUNT(G20:AZ20)/46) -> 0
A21: 17 | B21: آبان | C21: =IF(دانش‌آموزان!E6="","",دانش‌آموزان!B6) -> 2 | D21: =IF(دانش‌آموزان!C6="","",دانش‌آموزان!C6) -> 0980506328 | E21: =IF(دانش‌آموزان!E6="","",دانش‌آموزان!E6&" "&دانش‌آموزان!F6) -> اميررضا اميري | F21: =IF(دانش‌آموزان!I6="","",دانش‌آموزان!I6) -> 901 | CC21: =IF(COUNT(G21:N21)=0,"",AVERAGE(G21:N21)*4) | CD21: =IF(COUNT(O21:S21)=0,"",AVERAGE(O21:S21)*4) | CE21: =IF(COUNT(T21:U21)=0,"",AVERAGE(T21:U21)*4) | CF21: =IF(COUNT(V21:Z21)=0,"",AVERAGE(V21:Z21)*4) | CG21: =IF(COUNT(AA21:AC21)=0,"",AVERAGE(AA21:AC21)*4) | CH21: =IF(COUNT(AD21:AI21)=0,"",AVERAGE(AD21:AI21)*4) | CI21: =IF(COUNT(AJ21:AP21)=0,"",AVERAGE(AJ21:AP21)*4) | CJ21: =IF(COUNT(AQ21:AW21)=0,"",AVERAGE(AQ21:AW21)*4) | CK21: =IF(COUNT(AX21:AZ21)=0,"",AVERAGE(AX21:AZ21)*4) | CL21: =IF(C21="","",IF(COUNT(G21:AZ21)<46,"",SUMPRODUCT(CC21:CK21,'تنظیمات وزن‌دهی'!$C$5:$C$13)/100)) | CM21: =IF(C21="","",IF(COUNT(G21:AZ21)=0,"",IF(COUNT(G21:AZ21)<46,"موقت - اطلاعات ناقص",IF(CL21>=17,"عالی",IF(CL21>=14,"خوب",IF(CL21>=10,"متوسط","ضعیف")))))) | CN21: 5 | CO21: =IF(C21="","",COUNT(G21:AZ21)/46) -> 0
A22: 18 | B22: آذر | C22: =IF(دانش‌آموزان!E6="","",دانش‌آموزان!B6) -> 2 | D22: =IF(دانش‌آموزان!C6="","",دانش‌آموزان!C6) -> 0980506328 | E22: =IF(دانش‌آموزان!E6="","",دانش‌آموزان!E6&" "&دانش‌آموزان!F6) -> اميررضا اميري | F22: =IF(دانش‌آموزان!I6="","",دانش‌آموزان!I6) -> 901 | CC22: =IF(COUNT(G22:N22)=0,"",AVERAGE(G22:N22)*4) | CD22: =IF(COUNT(O22:S22)=0,"",AVERAGE(O22:S22)*4) | CE22: =IF(COUNT(T22:U22)=0,"",AVERAGE(T22:U22)*4) | CF22: =IF(COUNT(V22:Z22)=0,"",AVERAGE(V22:Z22)*4) | CG22: =IF(COUNT(AA22:AC22)=0,"",AVERAGE(AA22:AC22)*4) | CH22: =IF(COUNT(AD22:AI22)=0,"",AVERAGE(AD22:AI22)*4) | CI22: =IF(COUNT(AJ22:AP22)=0,"",AVERAGE(AJ22:AP22)*4) | CJ22: =IF(COUNT(AQ22:AW22)=0,"",AVERAGE(AQ22:AW22)*4) | CK22: =IF(COUNT(AX22:AZ22)=0,"",AVERAGE(AX22:AZ22)*4) | CL22: =IF(C22="","",IF(COUNT(G22:AZ22)<46,"",SUMPRODUCT(CC22:CK22,'تنظیمات وزن‌دهی'!$C$5:$C$13)/100)) | CM22: =IF(C22="","",IF(COUNT(G22:AZ22)=0,"",IF(COUNT(G22:AZ22)<46,"موقت - اطلاعات ناقص",IF(CL22>=17,"عالی",IF(CL22>=14,"خوب",IF(CL22>=10,"متوسط","ضعیف")))))) | CN22: 6 | CO22: =IF(C22="","",COUNT(G22:AZ22)/46) -> 0
A23: 19 | B23: دی | C23: =IF(دانش‌آموزان!E6="","",دانش‌آموزان!B6) -> 2 | D23: =IF(دانش‌آموزان!C6="","",دانش‌آموزان!C6) -> 0980506328 | E23: =IF(دانش‌آموزان!E6="","",دانش‌آموزان!E6&" "&دانش‌آموزان!F6) -> اميررضا اميري | F23: =IF(دانش‌آموزان!I6="","",دانش‌آموزان!I6) -> 901 | CC23: =IF(COUNT(G23:N23)=0,"",AVERAGE(G23:N23)*4) | CD23: =IF(COUNT(O23:S23)=0,"",AVERAGE(O23:S23)*4) | CE23: =IF(COUNT(T23:U23)=0,"",AVERAGE(T23:U23)*4) | CF23: =IF(COUNT(V23:Z23)=0,"",AVERAGE(V23:Z23)*4) | CG23: =IF(COUNT(AA23:AC23)=0,"",AVERAGE(AA23:AC23)*4) | CH23: =IF(COUNT(AD23:AI23)=0,"",AVERAGE(AD23:AI23)*4) | CI23: =IF(COUNT(AJ23:AP23)=0,"",AVERAGE(AJ23:AP23)*4) | CJ23: =IF(COUNT(AQ23:AW23)=0,"",AVERAGE(AQ23:AW23)*4) | CK23: =IF(COUNT(AX23:AZ23)=0,"",AVERAGE(AX23:AZ23)*4) | CL23: =IF(C23="","",IF(COUNT(G23:AZ23)<46,"",SUMPRODUCT(CC23:CK23,'تنظیمات وزن‌دهی'!$C$5:$C$13)/100)) | CM23: =IF(C23="","",IF(COUNT(G23:AZ23)=0,"",IF(COUNT(G23:AZ23)<46,"موقت - اطلاعات ناقص",IF(CL23>=17,"عالی",IF(CL23>=14,"خوب",IF(CL23>=10,"متوسط","ضعیف")))))) | CN23: 7 | CO23: =IF(C23="","",COUNT(G23:AZ23)/46) -> 0
A24: 20 | B24: بهمن | C24: =IF(دانش‌آموزان!E6="","",دانش‌آموزان!B6) -> 2 | D24: =IF(دانش‌آموزان!C6="","",دانش‌آموزان!C6) -> 0980506328 | E24: =IF(دانش‌آموزان!E6="","",دانش‌آموزان!E6&" "&دانش‌آموزان!F6) -> اميررضا اميري | F24: =IF(دانش‌آموزان!I6="","",دانش‌آموزان!I6) -> 901 | CC24: =IF(COUNT(G24:N24)=0,"",AVERAGE(G24:N24)*4) | CD24: =IF(COUNT(O24:S24)=0,"",AVERAGE(O24:S24)*4) | CE24: =IF(COUNT(T24:U24)=0,"",AVERAGE(T24:U24)*4) | CF24: =IF(COUNT(V24:Z24)=0,"",AVERAGE(V24:Z24)*4) | CG24: =IF(COUNT(AA24:AC24)=0,"",AVERAGE(AA24:AC24)*4) | CH24: =IF(COUNT(AD24:AI24)=0,"",AVERAGE(AD24:AI24)*4) | CI24: =IF(COUNT(AJ24:AP24)=0,"",AVERAGE(AJ24:AP24)*4) | CJ24: =IF(COUNT(AQ24:AW24)=0,"",AVERAGE(AQ24:AW24)*4) | CK24: =IF(COUNT(AX24:AZ24)=0,"",AVERAGE(AX24:AZ24)*4) | CL24: =IF(C24="","",IF(COUNT(G24:AZ24)<46,"",SUMPRODUCT(CC24:CK24,'تنظیمات وزن‌دهی'!$C$5:$C$13)/100)) | CM24: =IF(C24="","",IF(COUNT(G24:AZ24)=0,"",IF(COUNT(G24:AZ24)<46,"موقت - اطلاعات ناقص",IF(CL24>=17,"عالی",IF(CL24>=14,"خوب",IF(CL24>=10,"متوسط","ضعیف")))))) | CN24: 8 | CO24: =IF(C24="","",COUNT(G24:AZ24)/46) -> 0
A25: 21 | B25: اسفند | C25: =IF(دانش‌آموزان!E6="","",دانش‌آموزان!B6) -> 2 | D25: =IF(دانش‌آموزان!C6="","",دانش‌آموزان!C6) -> 0980506328 | E25: =IF(دانش‌آموزان!E6="","",دانش‌آموزان!E6&" "&دانش‌آموزان!F6) -> اميررضا اميري | F25: =IF(دانش‌آموزان!I6="","",دانش‌آموزان!I6) -> 901 | CC25: =IF(COUNT(G25:N25)=0,"",AVERAGE(G25:N25)*4) | CD25: =IF(COUNT(O25:S25)=0,"",AVERAGE(O25:S25)*4) | CE25: =IF(COUNT(T25:U25)=0,"",AVERAGE(T25:U25)*4) | CF25: =IF(COUNT(V25:Z25)=0,"",AVERAGE(V25:Z25)*4) | CG25: =IF(COUNT(AA25:AC25)=0,"",AVERAGE(AA25:AC25)*4) | CH25: =IF(COUNT(AD25:AI25)=0,"",AVERAGE(AD25:AI25)*4) | CI25: =IF(COUNT(AJ25:AP25)=0,"",AVERAGE(AJ25:AP25)*4) | CJ25: =IF(COUNT(AQ25:AW25)=0,"",AVERAGE(AQ25:AW25)*4) | CK25: =IF(COUNT(AX25:AZ25)=0,"",AVERAGE(AX25:AZ25)*4) | CL25: =IF(C25="","",IF(COUNT(G25:AZ25)<46,"",SUMPRODUCT(CC25:CK25,'تنظیمات وزن‌دهی'!$C$5:$C$13)/100)) | CM25: =IF(C25="","",IF(COUNT(G25:AZ25)=0,"",IF(COUNT(G25:AZ25)<46,"موقت - اطلاعات ناقص",IF(CL25>=17,"عالی",IF(CL25>=14,"خوب",IF(CL25>=10,"متوسط","ضعیف")))))) | CN25: 9 | CO25: =IF(C25="","",COUNT(G25:AZ25)/46) -> 0
A26: 22 | B26: فروردین | C26: =IF(دانش‌آموزان!E6="","",دانش‌آموزان!B6) -> 2 | D26: =IF(دانش‌آموزان!C6="","",دانش‌آموزان!C6) -> 0980506328 | E26: =IF(دانش‌آموزان!E6="","",دانش‌آموزان!E6&" "&دانش‌آموزان!F6) -> اميررضا اميري | F26: =IF(دانش‌آموزان!I6="","",دانش‌آموزان!I6) -> 901 | CC26: =IF(COUNT(G26:N26)=0,"",AVERAGE(G26:N26)*4) | CD26: =IF(COUNT(O26:S26)=0,"",AVERAGE(O26:S26)*4) | CE26: =IF(COUNT(T26:U26)=0,"",AVERAGE(T26:U26)*4) | CF26: =IF(COUNT(V26:Z26)=0,"",AVERAGE(V26:Z26)*4) | CG26: =IF(COUNT(AA26:AC26)=0,"",AVERAGE(AA26:AC26)*4) | CH26: =IF(COUNT(AD26:AI26)=0,"",AVERAGE(AD26:AI26)*4) | CI26: =IF(COUNT(AJ26:AP26)=0,"",AVERAGE(AJ26:AP26)*4) | CJ26: =IF(COUNT(AQ26:AW26)=0,"",AVERAGE(AQ26:AW26)*4) | CK26: =IF(COUNT(AX26:AZ26)=0,"",AVERAGE(AX26:AZ26)*4) | CL26: =IF(C26="","",IF(COUNT(G26:AZ26)<46,"",SUMPRODUCT(CC26:CK26,'تنظیمات وزن‌دهی'!$C$5:$C$13)/100)) | CM26: =IF(C26="","",IF(COUNT(G26:AZ26)=0,"",IF(COUNT(G26:AZ26)<46,"موقت - اطلاعات ناقص",IF(CL26>=17,"عالی",IF(CL26>=14,"خوب",IF(CL26>=10,"متوسط","ضعیف")))))) | CN26: 10 | CO26: =IF(C26="","",COUNT(G26:AZ26)/46) -> 0
A27: 23 | B27: اردیبهشت | C27: =IF(دانش‌آموزان!E6="","",دانش‌آموزان!B6) -> 2 | D27: =IF(دانش‌آموزان!C6="","",دانش‌آموزان!C6) -> 0980506328 | E27: =IF(دانش‌آموزان!E6="","",دانش‌آموزان!E6&" "&دانش‌آموزان!F6) -> اميررضا اميري | F27: =IF(دانش‌آموزان!I6="","",دانش‌آموزان!I6) -> 901 | CC27: =IF(COUNT(G27:N27)=0,"",AVERAGE(G27:N27)*4) | CD27: =IF(COUNT(O27:S27)=0,"",AVERAGE(O27:S27)*4) | CE27: =IF(COUNT(T27:U27)=0,"",AVERAGE(T27:U27)*4) | CF27: =IF(COUNT(V27:Z27)=0,"",AVERAGE(V27:Z27)*4) | CG27: =IF(COUNT(AA27:AC27)=0,"",AVERAGE(AA27:AC27)*4) | CH27: =IF(COUNT(AD27:AI27)=0,"",AVERAGE(AD27:AI27)*4) | CI27: =IF(COUNT(AJ27:AP27)=0,"",AVERAGE(AJ27:AP27)*4) | CJ27: =IF(COUNT(AQ27:AW27)=0,"",AVERAGE(AQ27:AW27)*4) | CK27: =IF(COUNT(AX27:AZ27)=0,"",AVERAGE(AX27:AZ27)*4) | CL27: =IF(C27="","",IF(COUNT(G27:AZ27)<46,"",SUMPRODUCT(CC27:CK27,'تنظیمات وزن‌دهی'!$C$5:$C$13)/100)) | CM27: =IF(C27="","",IF(COUNT(G27:AZ27)=0,"",IF(COUNT(G27:AZ27)<46,"موقت - اطلاعات ناقص",IF(CL27>=17,"عالی",IF(CL27>=14,"خوب",IF(CL27>=10,"متوسط","ضعیف")))))) | CN27: 11 | CO27: =IF(C27="","",COUNT(G27:AZ27)/46) -> 0
A28: 24 | B28: خرداد | C28: =IF(دانش‌آموزان!E6="","",دانش‌آموزان!B6) -> 2 | D28: =IF(دانش‌آموزان!C6="","",دانش‌آموزان!C6) -> 0980506328 | E28: =IF(دانش‌آموزان!E6="","",دانش‌آموزان!E6&" "&دانش‌آموزان!F6) -> اميررضا اميري | F28: =IF(دانش‌آموزان!I6="","",دانش‌آموزان!I6) -> 901 | CC28: =IF(COUNT(G28:N28)=0,"",AVERAGE(G28:N28)*4) | CD28: =IF(COUNT(O28:S28)=0,"",AVERAGE(O28:S28)*4) | CE28: =IF(COUNT(T28:U28)=0,"",AVERAGE(T28:U28)*4) | CF28: =IF(COUNT(V28:Z28)=0,"",AVERAGE(V28:Z28)*4) | CG28: =IF(COUNT(AA28:AC28)=0,"",AVERAGE(AA28:AC28)*4) | CH28: =IF(COUNT(AD28:AI28)=0,"",AVERAGE(AD28:AI28)*4) | CI28: =IF(COUNT(AJ28:AP28)=0,"",AVERAGE(AJ28:AP28)*4) | CJ28: =IF(COUNT(AQ28:AW28)=0,"",AVERAGE(AQ28:AW28)*4) | CK28: =IF(COUNT(AX28:AZ28)=0,"",AVERAGE(AX28:AZ28)*4) | CL28: =IF(C28="","",IF(COUNT(G28:AZ28)<46,"",SUMPRODUCT(CC28:CK28,'تنظیمات وزن‌دهی'!$C$5:$C$13)/100)) | CM28: =IF(C28="","",IF(COUNT(G28:AZ28)=0,"",IF(COUNT(G28:AZ28)<46,"موقت - اطلاعات ناقص",IF(CL28>=17,"عالی",IF(CL28>=14,"خوب",IF(CL28>=10,"متوسط","ضعیف")))))) | CN28: 12 | CO28: =IF(C28="","",COUNT(G28:AZ28)/46) -> 0
A29: 25 | B29: تیر | C29: =IF(دانش‌آموزان!E7="","",دانش‌آموزان!B7) -> 3 | D29: =IF(دانش‌آموزان!C7="","",دانش‌آموزان!C7) -> 0960300473 | E29: =IF(دانش‌آموزان!E7="","",دانش‌آموزان!E7&" "&دانش‌آموزان!F7) -> محمدامين باقري | F29: =IF(دانش‌آموزان!I7="","",دانش‌آموزان!I7) -> 901 | CC29: =IF(COUNT(G29:N29)=0,"",AVERAGE(G29:N29)*4) | CD29: =IF(COUNT(O29:S29)=0,"",AVERAGE(O29:S29)*4) | CE29: =IF(COUNT(T29:U29)=0,"",AVERAGE(T29:U29)*4) | CF29: =IF(COUNT(V29:Z29)=0,"",AVERAGE(V29:Z29)*4) | CG29: =IF(COUNT(AA29:AC29)=0,"",AVERAGE(AA29:AC29)*4) | CH29: =IF(COUNT(AD29:AI29)=0,"",AVERAGE(AD29:AI29)*4) | CI29: =IF(COUNT(AJ29:AP29)=0,"",AVERAGE(AJ29:AP29)*4) | CJ29: =IF(COUNT(AQ29:AW29)=0,"",AVERAGE(AQ29:AW29)*4) | CK29: =IF(COUNT(AX29:AZ29)=0,"",AVERAGE(AX29:AZ29)*4) | CL29: =IF(C29="","",IF(COUNT(G29:AZ29)<46,"",SUMPRODUCT(CC29:CK29,'تنظیمات وزن‌دهی'!$C$5:$C$13)/100)) | CM29: =IF(C29="","",IF(COUNT(G29:AZ29)=0,"",IF(COUNT(G29:AZ29)<46,"موقت - اطلاعات ناقص",IF(CL29>=17,"عالی",IF(CL29>=14,"خوب",IF(CL29>=10,"متوسط","ضعیف")))))) | CN29: 1 | CO29: =IF(C29="","",COUNT(G29:AZ29)/46) -> 0
A30: 26 | B30: مرداد | C30: =IF(دانش‌آموزان!E7="","",دانش‌آموزان!B7) -> 3 | D30: =IF(دانش‌آموزان!C7="","",دانش‌آموزان!C7) -> 0960300473 | E30: =IF(دانش‌آموزان!E7="","",دانش‌آموزان!E7&" "&دانش‌آموزان!F7) -> محمدامين باقري | F30: =IF(دانش‌آموزان!I7="","",دانش‌آموزان!I7) -> 901 | CC30: =IF(COUNT(G30:N30)=0,"",AVERAGE(G30:N30)*4) | CD30: =IF(COUNT(O30:S30)=0,"",AVERAGE(O30:S30)*4) | CE30: =IF(COUNT(T30:U30)=0,"",AVERAGE(T30:U30)*4) | CF30: =IF(COUNT(V30:Z30)=0,"",AVERAGE(V30:Z30)*4) | CG30: =IF(COUNT(AA30:AC30)=0,"",AVERAGE(AA30:AC30)*4) | CH30: =IF(COUNT(AD30:AI30)=0,"",AVERAGE(AD30:AI30)*4) | CI30: =IF(COUNT(AJ30:AP30)=0,"",AVERAGE(AJ30:AP30)*4) | CJ30: =IF(COUNT(AQ30:AW30)=0,"",AVERAGE(AQ30:AW30)*4) | CK30: =IF(COUNT(AX30:AZ30)=0,"",AVERAGE(AX30:AZ30)*4) | CL30: =IF(C30="","",IF(COUNT(G30:AZ30)<46,"",SUMPRODUCT(CC30:CK30,'تنظیمات وزن‌دهی'!$C$5:$C$13)/100)) | CM30: =IF(C30="","",IF(COUNT(G30:AZ30)=0,"",IF(COUNT(G30:AZ30)<46,"موقت - اطلاعات ناقص",IF(CL30>=17,"عالی",IF(CL30>=14,"خوب",IF(CL30>=10,"متوسط","ضعیف")))))) | CN30: 2 | CO30: =IF(C30="","",COUNT(G30:AZ30)/46) -> 0
A31: 27 | B31: شهریور | C31: =IF(دانش‌آموزان!E7="","",دانش‌آموزان!B7) -> 3 | D31: =IF(دانش‌آموزان!C7="","",دانش‌آموزان!C7) -> 0960300473 | E31: =IF(دانش‌آموزان!E7="","",دانش‌آموزان!E7&" "&دانش‌آموزان!F7) -> محمدامين باقري | F31: =IF(دانش‌آموزان!I7="","",دانش‌آموزان!I7) -> 901 | G31: 19.43 | H31: 0 | I31: 0 | J31: 3 | K31: 0 | L31: 0 | M31: 0 | N31: 0 | O31: 3 | P31: 3 | Q31: 3 | R31: 3 | S31: 0 | T31: 0 | U31: 4 | V31: 2 | W31: 3 | X31: 3 | Y31: 4 | Z31: 4 | AA31: 0 | AB31: 0 | AC31: 0 | AD31: 0 | AE31: 0 | AF31: 0 | AG31: 0 | AH31: 0 | AI31: 0 | AJ31: 0 | AK31: 0 | AL31: 0 | AM31: 0 | AN31: 0 | AO31: 0 | AP31: 0 | AQ31: 0 | AR31: 0 | AS31: 0 | AT31: 0 | AU31: 0 | AV31: 0 | AW31: 0 | AX31: 0 | AY31: 0 | AZ31: 0 | CC31: =IF(COUNT(G31:N31)=0,"",AVERAGE(G31:N31)*4) -> 11.215 | CD31: =IF(COUNT(O31:S31)=0,"",AVERAGE(O31:S31)*4) -> 9.6 | CE31: =IF(COUNT(T31:U31)=0,"",AVERAGE(T31:U31)*4) -> 8 | CF31: =IF(COUNT(V31:Z31)=0,"",AVERAGE(V31:Z31)*4) -> 12.8 | CG31: =IF(COUNT(AA31:AC31)=0,"",AVERAGE(AA31:AC31)*4) -> 0 | CH31: =IF(COUNT(AD31:AI31)=0,"",AVERAGE(AD31:AI31)*4) -> 0 | CI31: =IF(COUNT(AJ31:AP31)=0,"",AVERAGE(AJ31:AP31)*4) -> 0 | CJ31: =IF(COUNT(AQ31:AW31)=0,"",AVERAGE(AQ31:AW31)*4) -> 0 | CK31: =IF(COUNT(AX31:AZ31)=0,"",AVERAGE(AX31:AZ31)*4) -> 0 | CL31: =IF(C31="","",IF(COUNT(G31:AZ31)<46,"",SUMPRODUCT(CC31:CK31,'تنظیمات وزن‌دهی'!$C$5:$C$13)/100)) -> #VALUE! | CM31: =IF(C31="","",IF(COUNT(G31:AZ31)=0,"",IF(COUNT(G31:AZ31)<46,"موقت - اطلاعات ناقص",IF(CL31>=17,"عالی",IF(CL31>=14,"خوب",IF(CL31>=10,"متوسط","ضعیف")))))) -> #VALUE! | CN31: 3 | CO31: =IF(C31="","",COUNT(G31:AZ31)/46) -> 1
A32: 28 | B32: مهر | C32: =IF(دانش‌آموزان!E7="","",دانش‌آموزان!B7) -> 3 | D32: =IF(دانش‌آموزان!C7="","",دانش‌آموزان!C7) -> 0960300473 | E32: =IF(دانش‌آموزان!E7="","",دانش‌آموزان!E7&" "&دانش‌آموزان!F7) -> محمدامين باقري | F32: =IF(دانش‌آموزان!I7="","",دانش‌آموزان!I7) -> 901 | CC32: =IF(COUNT(G32:N32)=0,"",AVERAGE(G32:N32)*4) | CD32: =IF(COUNT(O32:S32)=0,"",AVERAGE(O32:S32)*4) | CE32: =IF(COUNT(T32:U32)=0,"",AVERAGE(T32:U32)*4) | CF32: =IF(COUNT(V32:Z32)=0,"",AVERAGE(V32:Z32)*4) | CG32: =IF(COUNT(AA32:AC32)=0,"",AVERAGE(AA32:AC32)*4) | CH32: =IF(COUNT(AD32:AI32)=0,"",AVERAGE(AD32:AI32)*4) | CI32: =IF(COUNT(AJ32:AP32)=0,"",AVERAGE(AJ32:AP32)*4) | CJ32: =IF(COUNT(AQ32:AW32)=0,"",AVERAGE(AQ32:AW32)*4) | CK32: =IF(COUNT(AX32:AZ32)=0,"",AVERAGE(AX32:AZ32)*4) | CL32: =IF(C32="","",IF(COUNT(G32:AZ32)<46,"",SUMPRODUCT(CC32:CK32,'تنظیمات وزن‌دهی'!$C$5:$C$13)/100)) | CM32: =IF(C32="","",IF(COUNT(G32:AZ32)=0,"",IF(COUNT(G32:AZ32)<46,"موقت - اطلاعات ناقص",IF(CL32>=17,"عالی",IF(CL32>=14,"خوب",IF(CL32>=10,"متوسط","ضعیف")))))) | CN32: 4 | CO32: =IF(C32="","",COUNT(G32:AZ32)/46) -> 0
A33: 29 | B33: آبان | C33: =IF(دانش‌آموزان!E7="","",دانش‌آموزان!B7) -> 3 | D33: =IF(دانش‌آموزان!C7="","",دانش‌آموزان!C7) -> 0960300473 | E33: =IF(دانش‌آموزان!E7="","",دانش‌آموزان!E7&" "&دانش‌آموزان!F7) -> محمدامين باقري | F33: =IF(دانش‌آموزان!I7="","",دانش‌آموزان!I7) -> 901 | CC33: =IF(COUNT(G33:N33)=0,"",AVERAGE(G33:N33)*4) | CD33: =IF(COUNT(O33:S33)=0,"",AVERAGE(O33:S33)*4) | CE33: =IF(COUNT(T33:U33)=0,"",AVERAGE(T33:U33)*4) | CF33: =IF(COUNT(V33:Z33)=0,"",AVERAGE(V33:Z33)*4) | CG33: =IF(COUNT(AA33:AC33)=0,"",AVERAGE(AA33:AC33)*4) | CH33: =IF(COUNT(AD33:AI33)=0,"",AVERAGE(AD33:AI33)*4) | CI33: =IF(COUNT(AJ33:AP33)=0,"",AVERAGE(AJ33:AP33)*4) | CJ33: =IF(COUNT(AQ33:AW33)=0,"",AVERAGE(AQ33:AW33)*4) | CK33: =IF(COUNT(AX33:AZ33)=0,"",AVERAGE(AX33:AZ33)*4) | CL33: =IF(C33="","",IF(COUNT(G33:AZ33)<46,"",SUMPRODUCT(CC33:CK33,'تنظیمات وزن‌دهی'!$C$5:$C$13)/100)) | CM33: =IF(C33="","",IF(COUNT(G33:AZ33)=0,"",IF(COUNT(G33:AZ33)<46,"موقت - اطلاعات ناقص",IF(CL33>=17,"عالی",IF(CL33>=14,"خوب",IF(CL33>=10,"متوسط","ضعیف")))))) | CN33: 5 | CO33: =IF(C33="","",COUNT(G33:AZ33)/46) -> 0
A34: 30 | B34: آذر | C34: =IF(دانش‌آموزان!E7="","",دانش‌آموزان!B7) -> 3 | D34: =IF(دانش‌آموزان!C7="","",دانش‌آموزان!C7) -> 0960300473 | E34: =IF(دانش‌آموزان!E7="","",دانش‌آموزان!E7&" "&دانش‌آموزان!F7) -> محمدامين باقري | F34: =IF(دانش‌آموزان!I7="","",دانش‌آموزان!I7) -> 901 | CC34: =IF(COUNT(G34:N34)=0,"",AVERAGE(G34:N34)*4) | CD34: =IF(COUNT(O34:S34)=0,"",AVERAGE(O34:S34)*4) | CE34: =IF(COUNT(T34:U34)=0,"",AVERAGE(T34:U34)*4) | CF34: =IF(COUNT(V34:Z34)=0,"",AVERAGE(V34:Z34)*4) | CG34: =IF(COUNT(AA34:AC34)=0,"",AVERAGE(AA34:AC34)*4) | CH34: =IF(COUNT(AD34:AI34)=0,"",AVERAGE(AD34:AI34)*4) | CI34: =IF(COUNT(AJ34:AP34)=0,"",AVERAGE(AJ34:AP34)*4) | CJ34: =IF(COUNT(AQ34:AW34)=0,"",AVERAGE(AQ34:AW34)*4) | CK34: =IF(COUNT(AX34:AZ34)=0,"",AVERAGE(AX34:AZ34)*4) | CL34: =IF(C34="","",IF(COUNT(G34:AZ34)<46,"",SUMPRODUCT(CC34:CK34,'تنظیمات وزن‌دهی'!$C$5:$C$13)/100)) | CM34: =IF(C34="","",IF(COUNT(G34:AZ34)=0,"",IF(COUNT(G34:AZ34)<46,"موقت - اطلاعات ناقص",IF(CL34>=17,"عالی",IF(CL34>=14,"خوب",IF(CL34>=10,"متوسط","ضعیف")))))) | CN34: 6 | CO34: =IF(C34="","",COUNT(G34:AZ34)/46) -> 0
A35: 31 | B35: دی | C35: =IF(دانش‌آموزان!E7="","",دانش‌آموزان!B7) -> 3 | D35: =IF(دانش‌آموزان!C7="","",دانش‌آموزان!C7) -> 0960300473 | E35: =IF(دانش‌آموزان!E7="","",دانش‌آموزان!E7&" "&دانش‌آموزان!F7) -> محمدامين باقري | F35: =IF(دانش‌آموزان!I7="","",دانش‌آموزان!I7) -> 901 | CC35: =IF(COUNT(G35:N35)=0,"",AVERAGE(G35:N35)*4) | CD35: =IF(COUNT(O35:S35)=0,"",AVERAGE(O35:S35)*4) | CE35: =IF(COUNT(T35:U35)=0,"",AVERAGE(T35:U35)*4) | CF35: =IF(COUNT(V35:Z35)=0,"",AVERAGE(V35:Z35)*4) | CG35: =IF(COUNT(AA35:AC35)=0,"",AVERAGE(AA35:AC35)*4) | CH35: =IF(COUNT(AD35:AI35)=0,"",AVERAGE(AD35:AI35)*4) | CI35: =IF(COUNT(AJ35:AP35)=0,"",AVERAGE(AJ35:AP35)*4) | CJ35: =IF(COUNT(AQ35:AW35)=0,"",AVERAGE(AQ35:AW35)*4) | CK35: =IF(COUNT(AX35:AZ35)=0,"",AVERAGE(AX35:AZ35)*4) | CL35: =IF(C35="","",IF(COUNT(G35:AZ35)<46,"",SUMPRODUCT(CC35:CK35,'تنظیمات وزن‌دهی'!$C$5:$C$13)/100)) | CM35: =IF(C35="","",IF(COUNT(G35:AZ35)=0,"",IF(COUNT(G35:AZ35)<46,"موقت - اطلاعات ناقص",IF(CL35>=17,"عالی",IF(CL35>=14,"خوب",IF(CL35>=10,"متوسط","ضعیف")))))) | CN35: 7 | CO35: =IF(C35="","",COUNT(G35:AZ35)/46) -> 0
A36: 32 | B36: بهمن | C36: =IF(دانش‌آموزان!E7="","",دانش‌آموزان!B7) -> 3 | D36: =IF(دانش‌آموزان!C7="","",دانش‌آموزان!C7) -> 0960300473 | E36: =IF(دانش‌آموزان!E7="","",دانش‌آموزان!E7&" "&دانش‌آموزان!F7) -> محمدامين باقري | F36: =IF(دانش‌آموزان!I7="","",دانش‌آموزان!I7) -> 901 | CC36: =IF(COUNT(G36:N36)=0,"",AVERAGE(G36:N36)*4) | CD36: =IF(COUNT(O36:S36)=0,"",AVERAGE(O36:S36)*4) | CE36: =IF(COUNT(T36:U36)=0,"",AVERAGE(T36:U36)*4) | CF36: =IF(COUNT(V36:Z36)=0,"",AVERAGE(V36:Z36)*4) | CG36: =IF(COUNT(AA36:AC36)=0,"",AVERAGE(AA36:AC36)*4) | CH36: =IF(COUNT(AD36:AI36)=0,"",AVERAGE(AD36:AI36)*4) | CI36: =IF(COUNT(AJ36:AP36)=0,"",AVERAGE(AJ36:AP36)*4) | CJ36: =IF(COUNT(AQ36:AW36)=0,"",AVERAGE(AQ36:AW36)*4) | CK36: =IF(COUNT(AX36:AZ36)=0,"",AVERAGE(AX36:AZ36)*4) | CL36: =IF(C36="","",IF(COUNT(G36:AZ36)<46,"",SUMPRODUCT(CC36:CK36,'تنظیمات وزن‌دهی'!$C$5:$C$13)/100)) | CM36: =IF(C36="","",IF(COUNT(G36:AZ36)=0,"",IF(COUNT(G36:AZ36)<46,"موقت - اطلاعات ناقص",IF(CL36>=17,"عالی",IF(CL36>=14,"خوب",IF(CL36>=10,"متوسط","ضعیف")))))) | CN36: 8 | CO36: =IF(C36="","",COUNT(G36:AZ36)/46) -> 0
A37: 33 | B37: اسفند | C37: =IF(دانش‌آموزان!E7="","",دانش‌آموزان!B7) -> 3 | D37: =IF(دانش‌آموزان!C7="","",دانش‌آموزان!C7) -> 0960300473 | E37: =IF(دانش‌آموزان!E7="","",دانش‌آموزان!E7&" "&دانش‌آموزان!F7) -> محمدامين باقري | F37: =IF(دانش‌آموزان!I7="","",دانش‌آموزان!I7) -> 901 | CC37: =IF(COUNT(G37:N37)=0,"",AVERAGE(G37:N37)*4) | CD37: =IF(COUNT(O37:S37)=0,"",AVERAGE(O37:S37)*4) | CE37: =IF(COUNT(T37:U37)=0,"",AVERAGE(T37:U37)*4) | CF37: =IF(COUNT(V37:Z37)=0,"",AVERAGE(V37:Z37)*4) | CG37: =IF(COUNT(AA37:AC37)=0,"",AVERAGE(AA37:AC37)*4) | CH37: =IF(COUNT(AD37:AI37)=0,"",AVERAGE(AD37:AI37)*4) | CI37: =IF(COUNT(AJ37:AP37)=0,"",AVERAGE(AJ37:AP37)*4) | CJ37: =IF(COUNT(AQ37:AW37)=0,"",AVERAGE(AQ37:AW37)*4) | CK37: =IF(COUNT(AX37:AZ37)=0,"",AVERAGE(AX37:AZ37)*4) | CL37: =IF(C37="","",IF(COUNT(G37:AZ37)<46,"",SUMPRODUCT(CC37:CK37,'تنظیمات وزن‌دهی'!$C$5:$C$13)/100)) | CM37: =IF(C37="","",IF(COUNT(G37:AZ37)=0,"",IF(COUNT(G37:AZ37)<46,"موقت - اطلاعات ناقص",IF(CL37>=17,"عالی",IF(CL37>=14,"خوب",IF(CL37>=10,"متوسط","ضعیف")))))) | CN37: 9 | CO37: =IF(C37="","",COUNT(G37:AZ37)/46) -> 0
A38: 34 | B38: فروردین | C38: =IF(دانش‌آموزان!E7="","",دانش‌آموزان!B7) -> 3 | D38: =IF(دانش‌آموزان!C7="","",دانش‌آموزان!C7) -> 0960300473 | E38: =IF(دانش‌آموزان!E7="","",دانش‌آموزان!E7&" "&دانش‌آموزان!F7) -> محمدامين باقري | F38: =IF(دانش‌آموزان!I7="","",دانش‌آموزان!I7) -> 901 | CC38: =IF(COUNT(G38:N38)=0,"",AVERAGE(G38:N38)*4) | CD38: =IF(COUNT(O38:S38)=0,"",AVERAGE(O38:S38)*4) | CE38: =IF(COUNT(T38:U38)=0,"",AVERAGE(T38:U38)*4) | CF38: =IF(COUNT(V38:Z38)=0,"",AVERAGE(V38:Z38)*4) | CG38: =IF(COUNT(AA38:AC38)=0,"",AVERAGE(AA38:AC38)*4) | CH38: =IF(COUNT(AD38:AI38)=0,"",AVERAGE(AD38:AI38)*4) | CI38: =IF(COUNT(AJ38:AP38)=0,"",AVERAGE(AJ38:AP38)*4) | CJ38: =IF(COUNT(AQ38:AW38)=0,"",AVERAGE(AQ38:AW38)*4) | CK38: =IF(COUNT(AX38:AZ38)=0,"",AVERAGE(AX38:AZ38)*4) | CL38: =IF(C38="","",IF(COUNT(G38:AZ38)<46,"",SUMPRODUCT(CC38:CK38,'تنظیمات وزن‌دهی'!$C$5:$C$13)/100)) | CM38: =IF(C38="","",IF(COUNT(G38:AZ38)=0,"",IF(COUNT(G38:AZ38)<46,"موقت - اطلاعات ناقص",IF(CL38>=17,"عالی",IF(CL38>=14,"خوب",IF(CL38>=10,"متوسط","ضعیف")))))) | CN38: 10 | CO38: =IF(C38="","",COUNT(G38:AZ38)/46) -> 0
A39: 35 | B39: اردیبهشت | C39: =IF(دانش‌آموزان!E7="","",دانش‌آموزان!B7) -> 3 | D39: =IF(دانش‌آموزان!C7="","",دانش‌آموزان!C7) -> 0960300473 | E39: =IF(دانش‌آموزان!E7="","",دانش‌آموزان!E7&" "&دانش‌آموزان!F7) -> محمدامين باقري | F39: =IF(دانش‌آموزان!I7="","",دانش‌آموزان!I7) -> 901 | CC39: =IF(COUNT(G39:N39)=0,"",AVERAGE(G39:N39)*4) | CD39: =IF(COUNT(O39:S39)=0,"",AVERAGE(O39:S39)*4) | CE39: =IF(COUNT(T39:U39)=0,"",AVERAGE(T39:U39)*4) | CF39: =IF(COUNT(V39:Z39)=0,"",AVERAGE(V39:Z39)*4) | CG39: =IF(COUNT(AA39:AC39)=0,"",AVERAGE(AA39:AC39)*4) | CH39: =IF(COUNT(AD39:AI39)=0,"",AVERAGE(AD39:AI39)*4) | CI39: =IF(COUNT(AJ39:AP39)=0,"",AVERAGE(AJ39:AP39)*4) | CJ39: =IF(COUNT(AQ39:AW39)=0,"",AVERAGE(AQ39:AW39)*4) | CK39: =IF(COUNT(AX39:AZ39)=0,"",AVERAGE(AX39:AZ39)*4) | CL39: =IF(C39="","",IF(COUNT(G39:AZ39)<46,"",SUMPRODUCT(CC39:CK39,'تنظیمات وزن‌دهی'!$C$5:$C$13)/100)) | CM39: =IF(C39="","",IF(COUNT(G39:AZ39)=0,"",IF(COUNT(G39:AZ39)<46,"موقت - اطلاعات ناقص",IF(CL39>=17,"عالی",IF(CL39>=14,"خوب",IF(CL39>=10,"متوسط","ضعیف")))))) | CN39: 11 | CO39: =IF(C39="","",COUNT(G39:AZ39)/46) -> 0
A40: 36 | B40: خرداد | C40: =IF(دانش‌آموزان!E7="","",دانش‌آموزان!B7) -> 3 | D40: =IF(دانش‌آموزان!C7="","",دانش‌آموزان!C7) -> 0960300473 | E40: =IF(دانش‌آموزان!E7="","",دانش‌آموزان!E7&" "&دانش‌آموزان!F7) -> محمدامين باقري | F40: =IF(دانش‌آموزان!I7="","",دانش‌آموزان!I7) -> 901 | CC40: =IF(COUNT(G40:N40)=0,"",AVERAGE(G40:N40)*4) | CD40: =IF(COUNT(O40:S40)=0,"",AVERAGE(O40:S40)*4) | CE40: =IF(COUNT(T40:U40)=0,"",AVERAGE(T40:U40)*4) | CF40: =IF(COUNT(V40:Z40)=0,"",AVERAGE(V40:Z40)*4) | CG40: =IF(COUNT(AA40:AC40)=0,"",AVERAGE(AA40:AC40)*4) | CH40: =IF(COUNT(AD40:AI40)=0,"",AVERAGE(AD40:AI40)*4) | CI40: =IF(COUNT(AJ40:AP40)=0,"",AVERAGE(AJ40:AP40)*4) | CJ40: =IF(COUNT(AQ40:AW40)=0,"",AVERAGE(AQ40:AW40)*4) | CK40: =IF(COUNT(AX40:AZ40)=0,"",AVERAGE(AX40:AZ40)*4) | CL40: =IF(C40="","",IF(COUNT(G40:AZ40)<46,"",SUMPRODUCT(CC40:CK40,'تنظیمات وزن‌دهی'!$C$5:$C$13)/100)) | CM40: =IF(C40="","",IF(COUNT(G40:AZ40)=0,"",IF(COUNT(G40:AZ40)<46,"موقت - اطلاعات ناقص",IF(CL40>=17,"عالی",IF(CL40>=14,"خوب",IF(CL40>=10,"متوسط","ضعیف")))))) | CN40: 12 | CO40: =IF(C40="","",COUNT(G40:AZ40)/46) -> 0
A41: 37 | B41: تیر | C41: =IF(دانش‌آموزان!E8="","",دانش‌آموزان!B8) -> 4 | D41: =IF(دانش‌آموزان!C8="","",دانش‌آموزان!C8) -> 0960412271 | E41: =IF(دانش‌آموزان!E8="","",دانش‌آموزان!E8&" "&دانش‌آموزان!F8) -> اميرحيدر ترابي | F41: =IF(دانش‌آموزان!I8="","",دانش‌آموزان!I8) -> 901 | CC41: =IF(COUNT(G41:N41)=0,"",AVERAGE(G41:N41)*4) | CD41: =IF(COUNT(O41:S41)=0,"",AVERAGE(O41:S41)*4) | CE41: =IF(COUNT(T41:U41)=0,"",AVERAGE(T41:U41)*4) | CF41: =IF(COUNT(V41:Z41)=0,"",AVERAGE(V41:Z41)*4) | CG41: =IF(COUNT(AA41:AC41)=0,"",AVERAGE(AA41:AC41)*4) | CH41: =IF(COUNT(AD41:AI41)=0,"",AVERAGE(AD41:AI41)*4) | CI41: =IF(COUNT(AJ41:AP41)=0,"",AVERAGE(AJ41:AP41)*4) | CJ41: =IF(COUNT(AQ41:AW41)=0,"",AVERAGE(AQ41:AW41)*4) | CK41: =IF(COUNT(AX41:AZ41)=0,"",AVERAGE(AX41:AZ41)*4) | CL41: =IF(C41="","",IF(COUNT(G41:AZ41)<46,"",SUMPRODUCT(CC41:CK41,'تنظیمات وزن‌دهی'!$C$5:$C$13)/100)) | CM41: =IF(C41="","",IF(COUNT(G41:AZ41)=0,"",IF(COUNT(G41:AZ41)<46,"موقت - اطلاعات ناقص",IF(CL41>=17,"عالی",IF(CL41>=14,"خوب",IF(CL41>=10,"متوسط","ضعیف")))))) | CN41: 1 | CO41: =IF(C41="","",COUNT(G41:AZ41)/46) -> 0
...

Sheet تحلیل دانش‌آموزان
A1: تحلیل دانش‌آموزان
A2: این شیت خودکار است. فقط ارزیابی‌های نهایی در میانگین، روند و رتبه وارد می‌شوند و تعداد واقعی افراد رتبه‌بندی‌شده نمایش داده می‌شود.
A4: کد محلی | B4: کد ملی | C4: نام و نام خانوادگی | D4: کد کلاس | E4: آموزشی | F4: پرورشی | G4: تربیتی | H4: انضباطی | I4: فرهنگی | J4: پژوهشی | K4: ورزشی | L4: هنری | M4: مهارت‌های فردی | N4: میانگین کل | O4: ماه نهایی | P4: اولین ماه | Q4: آخرین ماه | R4: میزان تغییر | S4: روند | T4: قوی‌ترین حوزه | U4: ضعیف‌ترین حوزه | V4: سطح | W4: رتبه | X4: تعداد رتبه‌بندی‌شده | Y4: پیشنهاد
